Workbook

Sheet Percentages
B1: Segment | C1: Average | D1: Weighted Avg*
B2: Basement | C2: =AVERAGE(Worksheet!H71,Worksheet!H119,Worksheet!H167,Worksheet!H287,Worksheet!H299,Worksheet!H311,Worksheet!H347,Worksheet!H443,Worksheet!H599,Worksheet!H611,Worksheet!H647,Worksheet!H719,Worksheet!H731,Worksheet!H767,Worksheet!H803,Worksheet!H851,Worksheet!H887,Worksheet!H899,Worksheet!H971,Worksheet!H1043,Worksheet!H1187) -> 0.54764468 | D2: =AVERAGE(Worksheet!H66:H68,Worksheet!H114,Worksheet!H115,Worksheet!H116,Worksheet!H162,Worksheet!H163,Worksheet!H164,Worksheet!H282,Worksheet!H283,Worksheet!H284,Worksheet!H294,Worksheet!H295,Worksheet!H296,Worksheet!H306,Worksheet!H307,Worksheet!H308,Worksheet!H342,Worksheet!H343,Worksheet!H344,Worksheet!H438,Worksheet!H439,Worksheet!H440,Worksheet!H594,Worksheet!H595,Worksheet!H596,Worksheet!H606,Worksheet!H607,Worksheet!H608,Worksheet!H642,Worksheet!H643,Worksheet!H644,Worksheet!H714,Worksheet!H715,Worksheet!H716,Worksheet!H727,Worksheet!H726,Worksheet!H728,Worksheet!H762,Worksheet!H763,Worksheet!H764,Worksheet!H798,Worksheet!H799,Worksheet!H800,Worksheet!H846,Worksheet!H847,Worksheet!H848,Worksheet!H882,Worksheet!H883,Worksheet!H884,Worksheet!H894,Worksheet!H895,Worksheet!H896,Worksheet!H966,Worksheet!H967,Worksheet!H968,Worksheet!H1038,Worksheet!H1039,Worksheet!H1040,Worksheet!H1182,Worksheet!H1183,Worksheet!H1184) -> 0.56631291
B3: Unfinished Basement | C3: =AVERAGE(Worksheet!L311,Worksheet!L491,Worksheet!L707,Worksheet!L887,Worksheet!L899,Worksheet!L935,Worksheet!L1043,Worksheet!L1067,Worksheet!L1187) -> 0.25600627 | D3: =AVERAGE(Worksheet!L306:L308,Worksheet!L486,Worksheet!L487,Worksheet!L488,Worksheet!L702,Worksheet!L703,Worksheet!L704,Worksheet!L882,Worksheet!L883,Worksheet!L884,Worksheet!L894,Worksheet!L895,Worksheet!L896,Worksheet!L930,Worksheet!L931,Worksheet!L932,Worksheet!L1038,Worksheet!L1039,Worksheet!L1040,Worksheet!L1062,Worksheet!L1063,Worksheet!L1064,Worksheet!L1182,Worksheet!L1183,Worksheet!L1184) -> 0.2635513
B4: Lower | C4: =AVERAGE(Worksheet!P11,Worksheet!P95,Worksheet!P191,Worksheet!P203,Worksheet!P251,Worksheet!P263,Worksheet!P275,Worksheet!P503,Worksheet!P527,Worksheet!P875,Worksheet!P923,Worksheet!P983,Worksheet!P995,Worksheet!P1007,Worksheet!P1019,Worksheet!P1031,Worksheet!P1055) -> 0.6033757 | D4: =AVERAGE(Worksheet!P6:P8,Worksheet!P90,Worksheet!P91,Worksheet!P92,Worksheet!P186,Worksheet!P187,Worksheet!P188,Worksheet!P198,Worksheet!P199,Worksheet!P200,Worksheet!P246,Worksheet!P247,Worksheet!P248,Worksheet!P258,Worksheet!P259,Worksheet!P260,Worksheet!P270,Worksheet!P271,Worksheet!P272,Worksheet!P498,Worksheet!P499,Worksheet!P500,Worksheet!P522,Worksheet!P523,Worksheet!P524,Worksheet!P870,Worksheet!P871,Worksheet!P872,Worksheet!P918,Worksheet!P919,Worksheet!P920,Worksheet!P978,Worksheet!P979,Worksheet!P980,Worksheet!P990,Worksheet!P991,Worksheet!P992,Worksheet!P1002,Worksheet!P1003,Worksheet!P1004,Worksheet!P1014,Worksheet!P1015,Worksheet!P1016,Worksheet!P1026,Worksheet!P1027,Worksheet!P1028,Worksheet!P1050,Worksheet!P1051,Worksheet!P1052) -> 0.62551365
B5: Unfinished Lower | C5: =AVERAGE(Worksheet!T1055,Worksheet!T1031,Worksheet!T1019,Worksheet!T1007,Worksheet!T923) -> 0.30030965 | D5: =AVERAGE(Worksheet!T918:T920,Worksheet!T1002,Worksheet!T1003,Worksheet!T1004,Worksheet!T1014,Worksheet!T1015,Worksheet!T1016,Worksheet!T1026,Worksheet!T1027,Worksheet!T1028,Worksheet!T1050,Worksheet!T1051,Worksheet!T1052) -> 0.30495906
B6: 1/2 Story | C6: =AVERAGE(Worksheet!X575,Worksheet!X611,Worksheet!X623,Worksheet!X659,Worksheet!X671,Worksheet!X695,Worksheet!X707,Worksheet!X815,Worksheet!X827,Worksheet!X839,Worksheet!X851,Worksheet!X863,Worksheet!X935) -> 0.67280247 | D6: =AVERAGE(Worksheet!X570:X572,Worksheet!X606,Worksheet!X607,Worksheet!X608,Worksheet!X618,Worksheet!X619,Worksheet!X620,Worksheet!X654,Worksheet!X655,Worksheet!X656,Worksheet!X666,Worksheet!X667,Worksheet!X668,Worksheet!X690,Worksheet!X691,Worksheet!X692,Worksheet!X702,Worksheet!X703,Worksheet!X704,Worksheet!X810,Worksheet!X811,Worksheet!X812,Worksheet!X822,Worksheet!X823,Worksheet!X824,Worksheet!X834,Worksheet!X835,Worksheet!X836,Worksheet!X846,Worksheet!X847,Worksheet!X848,Worksheet!X858,Worksheet!X859,Worksheet!X860,Worksheet!X930,Worksheet!X931,Worksheet!X932) -> 0.68444942
B7: 2 Story | C7: =AVERAGE(Worksheet!AB71,Worksheet!AB107,Worksheet!AB143,Worksheet!AB179,Worksheet!AB191,Worksheet!AB227,Worksheet!AB239,Worksheet!AB263,Worksheet!AB275,Worksheet!AB287,Worksheet!AB299,Worksheet!AB323,Worksheet!AB359,Worksheet!AB395,Worksheet!AB467,Worksheet!AB479,Worksheet!AB515,Worksheet!AB527,Worksheet!AB623,Worksheet!AB803,Worksheet!AB875,Worksheet!AB947,Worksheet!AB959,Worksheet!AB983,Worksheet!AB1019,Worksheet!AB1127,Worksheet!AB1163,Worksheet!AB1175) -> 0.83018775 | D7: =AVERAGE(Worksheet!AB66:AB68,Worksheet!AB102,Worksheet!AB103,Worksheet!AB104,Worksheet!AB138,Worksheet!AB140,Worksheet!AB139,Worksheet!AB174,Worksheet!AB175,Worksheet!AB176,Worksheet!AB186,Worksheet!AB187,Worksheet!AB188,Worksheet!AB222,Worksheet!AB223,Worksheet!AB224,Worksheet!AB234,Worksheet!AB235,Worksheet!AB236,Worksheet!AB258,Worksheet!AB259,Worksheet!AB260,Worksheet!AB270,Worksheet!AB271,Worksheet!AB272,Worksheet!AB282,Worksheet!AB283,Worksheet!AB284,Worksheet!AB294,Worksheet!AB295,Worksheet!AB296,Worksheet!AB318,Worksheet!AB319,Worksheet!AB320,Worksheet!AB354,Worksheet!AB355,Worksheet!AB356,Worksheet!AB390,Worksheet!AB391,Worksheet!AB392,Worksheet!AB462,Worksheet!AB463,Worksheet!AB464,Worksheet!AB474,Worksheet!AB475,Worksheet!AB476,Worksheet!AB510,Worksheet!AB511,Worksheet!AB512,Worksheet!AB522,Worksheet!AB523,Worksheet!AB524,Worksheet!AB618,Worksheet!AB619,Worksheet!AB620,Worksheet!AB798,Worksheet!AB799,Worksheet!AB800,Worksheet!AB870,Worksheet!AB871,Worksheet!AB872,Worksheet!AB942,Worksheet!AB943,Worksheet!AB944,Worksheet!AB954,Worksheet!AB955,Worksheet!AB956,Worksheet!AB978,Worksheet!AB979,Worksheet!AB980,Worksheet!AB1014,Worksheet!AB1015,Worksheet!AB1016,Worksheet!AB1122,Worksheet!AB1123,Worksheet!AB1124,Worksheet!AB1158,Worksheet!AB1159,Worksheet!AB1160,Worksheet!AB1170,Worksheet!AB1171,Worksheet!AB1172) -> 0.84076687 | E7: - includes 2 stories and uppers over garages.
B8: Attached Garage | C8: =AVERAGE(Worksheet!AF11,Worksheet!AF23,Worksheet!AF35,Worksheet!AF47,Worksheet!AF59,Worksheet!AF71,Worksheet!AF107,Worksheet!AF119,Worksheet!AF131,Worksheet!AF143,Worksheet!AF155,Worksheet!AF167,Worksheet!AF179,Worksheet!AF191,Worksheet!AF203,Worksheet!AF215,Worksheet!AF227,Worksheet!AF239,Worksheet!AF251,Worksheet!AF263,Worksheet!AF275,Worksheet!AF323,Worksheet!AF335,Worksheet!AF347,Worksheet!AF359,Worksheet!AF371,Worksheet!AF383,Worksheet!AF395,Worksheet!AF407,Worksheet!AF455,Worksheet!AF467,Worksheet!AF479,Worksheet!AF503,Worksheet!AF515,Worksheet!AF527,Worksheet!AF587,Worksheet!AF683,Worksheet!AF719,Worksheet!AF767,Worksheet!AF779,Worksheet!AF791,Worksheet!AF803,Worksheet!AF875,Worksheet!AF899,Worksheet!AF947,Worksheet!AF959,Worksheet!AF971,Worksheet!AF983,Worksheet!AF995,Worksheet!AF1007,Worksheet!AF1019,Worksheet!AF1031,Worksheet!AF1043,Worksheet!AF1055,Worksheet!AF1103,Worksheet!AF1139,Worksheet!AF1151,Worksheet!AF1163,Worksheet!AF1175,Worksheet!AF1187) -> 0.30653794 | D8: =AVERAGE(Worksheet!AF6:AF8,Worksheet!AF18,Worksheet!AF19,Worksheet!AF20,Worksheet!AF30,Worksheet!AF31,Worksheet!AF32,Worksheet!AF42,Worksheet!AF43,Worksheet!AF44,Worksheet!AF54,Worksheet!AF55,Worksheet!AF56,Worksheet!AF66,Worksheet!AF67,Worksheet!AF68,Worksheet!AF102,Worksheet!AF103,Worksheet!AF104,Worksheet!AF114,Worksheet!AF115,Worksheet!AF116,Worksheet!AF126,Worksheet!AF127,Worksheet!AF128,Worksheet!AF138,Worksheet!AF139,Worksheet!AF140,Worksheet!AF150,Worksheet!AF151,Worksheet!AF152,Worksheet!AF162,Worksheet!AF163,Worksheet!AF164,Worksheet!AF174,Worksheet!AF175,Worksheet!AF176,Worksheet!AF186,Worksheet!AF187,Worksheet!AF188,Worksheet!AF198,Worksheet!AF199,Worksheet!AF200,Worksheet!AF210,Worksheet!AF211,Worksheet!AF212,Worksheet!AF222,Worksheet!AF223,Worksheet!AF224,Worksheet!AF234,Worksheet!AF235,Worksheet!AF236,Worksheet!AF246,Worksheet!AF247,Worksheet!AF248,Worksheet!AF258,Worksheet!AF259,Worksheet!AF260,Worksheet!AF270,Worksheet!AF271,Worksheet!AF272,Worksheet!AF318,Worksheet!AF319,Worksheet!AF320,Worksheet!AF330,Worksheet!AF331,Worksheet!AF332,Worksheet!AF342,Worksheet!AF343,Worksheet!AF344,Worksheet!AF354,Worksheet!AF355,Worksheet!AF356,Worksheet!AF366,Worksheet!AF367,Worksheet!AF368,Worksheet!AF378,Worksheet!AF379,Worksheet!AF380,Worksheet!AF390,Worksheet!AF391,Worksheet!AF392,Worksheet!AF402,Worksheet!AF403,Worksheet!AF404,Worksheet!AF450,Worksheet!AF451,Worksheet!AF452,Worksheet!AF462,Worksheet!AF463,Worksheet!AF464,Worksheet!AF474,Worksheet!AF475,Worksheet!AF476,Worksheet!AF498,Worksheet!AF499,Worksheet!AF500,Worksheet!AF510,Worksheet!AF511,Worksheet!AF512,Worksheet!AF522,Worksheet!AF523,Worksheet!AF524,Worksheet!AF582,Worksheet!AF583,Worksheet!AF584,Worksheet!AF678,Worksheet!AF679,Worksheet!AF680,Worksheet!AF714,Worksheet!AF715,Worksheet!AF716,Worksheet!AF762,Worksheet!AF763,Worksheet!AF764,Worksheet!AF774,Worksheet!AF775,Worksheet!AF776,Worksheet!AF786,Worksheet!AF787,Worksheet!AF788,Worksheet!AF798,Worksheet!AF799,Worksheet!AF800) -> 0.32595932
B9: Porch | C9: =AVERAGE(Worksheet!AJ167,Worksheet!AJ515,Worksheet!AJ1187) -> 0.049030823 | D9: =AVERAGE(Worksheet!AJ162:AJ164,Worksheet!AJ510,Worksheet!AJ511,Worksheet!AJ512,Worksheet!AJ1182,Worksheet!AJ1183,Worksheet!AJ1184) -> 0.046019054
B10: Covered Porch | C10: =AVERAGE(Worksheet!AN23,Worksheet!AN47,Worksheet!AN107,Worksheet!AN119,Worksheet!AN131,Worksheet!AN143,Worksheet!AN155,Worksheet!AN167,Worksheet!AN215,Worksheet!AN227,Worksheet!AN239,Worksheet!AN251,Worksheet!AN287,Worksheet!AN299,Worksheet!AN323,Worksheet!AN335,Worksheet!AN347,Worksheet!AN371,Worksheet!AN383,Worksheet!AN395,Worksheet!AN407,Worksheet!AN419,Worksheet!AN431,Worksheet!AN455,Worksheet!AN467,Worksheet!AN479,Worksheet!AN491,Worksheet!AN551,Worksheet!AN563,Worksheet!AN587,Worksheet!AN611,Worksheet!AN647,Worksheet!AN659,Worksheet!AN719,Worksheet!AN731,Worksheet!AN743,Worksheet!AN767,Worksheet!AN779,Worksheet!AN803+Worksheet!AN839,Worksheet!AN887,Worksheet!AN911,Worksheet!AN947,Worksheet!AN959,Worksheet!AN971,Worksheet!AN1079,Worksheet!AN1091,Worksheet!AN1103,Worksheet!AN1115,Worksheet!AN1151) -> 0.19086124 | D10: =AVERAGE(Worksheet!AN18:AN20,Worksheet!AN42,Worksheet!AN43,Worksheet!AN44,Worksheet!AN102,Worksheet!AN103,Worksheet!AN104,Worksheet!AN114,Worksheet!AN115,Worksheet!AN116,Worksheet!AN126,Worksheet!AN127,Worksheet!AN128,Worksheet!AN138,Worksheet!AN139,Worksheet!AN140,Worksheet!AN150,Worksheet!AN151,Worksheet!AN152,Worksheet!AN162,Worksheet!AN163,Worksheet!AN164,Worksheet!AN210,Worksheet!AN211,Worksheet!AN212,Worksheet!AN222,Worksheet!AN223,Worksheet!AN224,Worksheet!AN234,Worksheet!AN235,Worksheet!AN236,Worksheet!AN246,Worksheet!AN247,Worksheet!AN249,Worksheet!AN282,Worksheet!AN283,Worksheet!AN284,Worksheet!AN294,Worksheet!AN295,Worksheet!AN296,Worksheet!AN318,Worksheet!AN319,Worksheet!AN320,Worksheet!AN330,Worksheet!AN331,Worksheet!AN332,Worksheet!AN342,Worksheet!AN343,Worksheet!AN344,Worksheet!AN366,Worksheet!AN367,Worksheet!AN368,Worksheet!AN378,Worksheet!AN379,Worksheet!AN380,Worksheet!AN390,Worksheet!AN391,Worksheet!AN392,Worksheet!AN402,Worksheet!AN403,Worksheet!AN404,Worksheet!AN414,Worksheet!AN415,Worksheet!AN416,Worksheet!AN426,Worksheet!AN427,Worksheet!AN428,Worksheet!AN450,Worksheet!AN451,Worksheet!AN452,Worksheet!AN462,Worksheet!AN463,Worksheet!AN464,Worksheet!AN474,Worksheet!AN475,Worksheet!AN476,Worksheet!AN486,Worksheet!AN487,Worksheet!AN488,Worksheet!AN546,Worksheet!AN547,Worksheet!AN548,Worksheet!AN558,Worksheet!AN559,Worksheet!AN560,Worksheet!AN582,Worksheet!AN583,Worksheet!AN584,Worksheet!AN606,Worksheet!AN607,Worksheet!AN608,Worksheet!AN642,Worksheet!AN643,Worksheet!AN644,Worksheet!AN655,Worksheet!AN654,Worksheet!AN656,Worksheet!AN714,Worksheet!AN715,Worksheet!AN716,Worksheet!AN726,Worksheet!AN727,Worksheet!AN728,Worksheet!AN738,Worksheet!AN739,Worksheet!AN740,Worksheet!AN762,Worksheet!AN763,Worksheet!AN764,Worksheet!AN774,Worksheet!AN775,Worksheet!AN776,Worksheet!AN798,Worksheet!AN799,Worksheet!AN800,Worksheet!AN834,Worksheet!AN835,Worksheet!AN836,Worksheet!AN882,Worksheet!AN883,Worksheet!AN884) -> 0.19566242 | E10: - includes RFX/Conc, Cnpy/Conc, & Port/Conc
B11: Deck | C11: =AVERAGE(Worksheet!AR59,Worksheet!AR71,Worksheet!AR95,Worksheet!AR119,Worksheet!AR191,Worksheet!AR203,Worksheet!AR227,Worksheet!AR263,Worksheet!AR275,Worksheet!AR299,Worksheet!AR503,Worksheet!AR515,Worksheet!AR527,Worksheet!AR599,Worksheet!AR707,Worksheet!AR743,Worksheet!AR791,Worksheet!AR923,Worksheet!AR971,Worksheet!AR1007,Worksheet!AR1019,Worksheet!AR1031,Worksheet!AR1055,Worksheet!AR1067,Worksheet!AR1127,Worksheet!AR1187) -> 0.16260722 | D11: =AVERAGE(Worksheet!AR54:AR56,Worksheet!AR66,Worksheet!AR67,Worksheet!AR68,Worksheet!AR90,Worksheet!AR91,Worksheet!AR92,Worksheet!AR114,Worksheet!AR115,Worksheet!AR116,Worksheet!AR186,Worksheet!AR187,Worksheet!AR188,Worksheet!AR198,Worksheet!AR199,Worksheet!AR200,Worksheet!AR222,Worksheet!AR223,Worksheet!AR224,Worksheet!AR258,Worksheet!AR259,Worksheet!AR260,Worksheet!AR270,Worksheet!AR271,Worksheet!AR272,Worksheet!AR294,Worksheet!AR295,Worksheet!AR296,Worksheet!AR498,Worksheet!AR499,Worksheet!AR500,Worksheet!AR510,Worksheet!AR511,Worksheet!AR512,Worksheet!AR522,Worksheet!AR523,Worksheet!AR524,Worksheet!AR594,Worksheet!AR595,Worksheet!AR596,Worksheet!AR702,Worksheet!AR704,Worksheet!AR703,Worksheet!AR738,Worksheet!AR739,Worksheet!AR740,Worksheet!AR786,Worksheet!AR787,Worksheet!AR788,Worksheet!AR918,Worksheet!AR919,Worksheet!AR920,Worksheet!AR966,Worksheet!AR967,Worksheet!AR968,Worksheet!AR1002,Worksheet!AR1003,Worksheet!AR1004,Worksheet!AR1014,Worksheet!AR1015,Worksheet!AR1016,Worksheet!AR1026,Worksheet!AR1027,Worksheet!AR1028,Worksheet!AR1050,Worksheet!AR1051,Worksheet!AR1052,Worksheet!AR1062,Worksheet!AR1063,Worksheet!AR1064,Worksheet!AR1122,Worksheet!AR1123,Worksheet!AR1124,Worksheet!AR1182,Worksheet!AR1183,Worksheet!AR1184) -> 0.16450197
B12: Covered Deck | C12: =AVERAGE(Worksheet!AV11,Worksheet!AV59,Worksheet!AV71,Worksheet!AV83,Worksheet!AV167,Worksheet!AV179,Worksheet!AV191,Worksheet!AV287,Worksheet!AV299,Worksheet!AV671,Worksheet!AV695,Worksheet!AV875,Worksheet!AV1067) -> 0.28756217 | D12: =AVERAGE(Worksheet!AV6:AV8,Worksheet!AV54,Worksheet!AV55,Worksheet!AV56,Worksheet!AV66,Worksheet!AV68,Worksheet!AV67,Worksheet!AV78,Worksheet!AV79,Worksheet!AV80,Worksheet!AV162,Worksheet!AV163,Worksheet!AV164,Worksheet!AV174,Worksheet!AV175,Worksheet!AV176,Worksheet!AV186,Worksheet!AV187,Worksheet!AV188,Worksheet!AV282,Worksheet!AV283,Worksheet!AV284,Worksheet!AV294,Worksheet!AV295,Worksheet!AV296,Worksheet!AV666,Worksheet!AV667,Worksheet!AV668,Worksheet!AV691,Worksheet!AV690,Worksheet!AV692,Worksheet!AV870:AV871,Worksheet!AV871,Worksheet!AV872,Worksheet!AV1062,Worksheet!AV1063,Worksheet!AV1064) -> 0.3009737
B13: Carport | C13: =AVERAGE(Worksheet!AZ311,Worksheet!AZ515,Worksheet!AZ539,Worksheet!AZ551,Worksheet!AZ563,Worksheet!AZ731,Worksheet!AZ743,Worksheet!AZ755,Worksheet!AZ779,Worksheet!AZ1127) -> 0.16411388 | D13: =AVERAGE(Worksheet!AZ306:AZ308,Worksheet!AZ510,Worksheet!AZ511,Worksheet!AZ512,Worksheet!AZ534,Worksheet!AZ535,Worksheet!AZ536,Worksheet!AZ546,Worksheet!AZ547,Worksheet!AZ548,Worksheet!AZ558,Worksheet!AZ559,Worksheet!AZ560,Worksheet!AZ726,Worksheet!AZ727,Worksheet!AZ728,Worksheet!AZ738,Worksheet!AZ739,Worksheet!AZ740,Worksheet!AZ750,Worksheet!AZ751,Worksheet!AZ752,Worksheet!AZ774,Worksheet!AZ775,Worksheet!AZ776,Worksheet!AZ1122,Worksheet!AZ1123,Worksheet!AZ1124) -> 0.17057072
B14: EFP/Sunroom | C14: =AVERAGE(Worksheet!BD491,Worksheet!BD635,Worksheet!BD647,Worksheet!BD659,Worksheet!BD671,Worksheet!BD695,Worksheet!BD887,Worksheet!BD899,Worksheet!BD911,Worksheet!BD1067) -> 0.56586092 | D14: =AVERAGE(Worksheet!BD78:BD80,Worksheet!BD486,Worksheet!BD487,Worksheet!BD488,Worksheet!BD630,Worksheet!BD631,Worksheet!BD632,Worksheet!BD642,Worksheet!BD643,Worksheet!BD644,Worksheet!BD654,Worksheet!BD655,Worksheet!BD656,Worksheet!BD666,Worksheet!BD667,Worksheet!BD668,Worksheet!BD690,Worksheet!BD691,Worksheet!BD692,Worksheet!BD882,Worksheet!BD883,Worksheet!BD884,Worksheet!BD894,Worksheet!BD895,Worksheet!BD896,Worksheet!BD906,Worksheet!BD907,Worksheet!BD908,Worksheet!BD1062,Worksheet!BD1063,Worksheet!BD1064) -> 0.59403758
B15: Balcony | C15: =AVERAGE(Worksheet!BD1175,Worksheet!BD1163) -> 0.29770386 | D15: =AVERAGE(Worksheet!BD1170,Worksheet!BD1171,Worksheet!BD1172,Worksheet!BD1158,Worksheet!BD1159,Worksheet!BD1160) -> 0.31572663
B17: *Weighted Average excludes Chp, Low, VGd, and Exc
B20: Formula for calculation:
B21: [(MA $/sq ft) X (Segment %)] X (Segment sq ft)

Sheet Worksheet
B1: Parcel ID: 110892040006008 | E1: Main area sq ft: | F1: 1424 | H1: HT: Tri-Level | J1: Year Built: | K1: 1976
E2: Basement | I2: Unfinished Basement | M2: Lower | Q2: Unfinished Lower | U2: 1/2 Story | Y2: 2nd Story | AC2: Attached Garage | AG2: Porch | AK2: Covered Porch | AO2: Deck | AS2: Covered Deck | AW2: Carport | BA2: EFP/Sunroom
A3: Grade | B3: Main Area $ | C3: MA $/Sq Ft | D3: Basic Allowance | E3: BsmtVal | F3: Bsmt SqFt | G3: BsmtVal/Sq Ft | H3: Bsmt % Base | I3: UnfBsmtVal | J3: UnfBsmt Sq Ft | K3: UnfBsmtVal/SqFt | L3: UnfBsmt % Base | M3: Lower Value | N3: Lower Sq Ft | O3: LowerVal/SqFt | P3: Lower % Base | Q3: Unf Lower Value | R3: UnfLower Sq Ft | S3: UnfLowVal/SqFt2 | T3: Unf Lower % Base | U3: 1/2 Story Value | V3: 1/2 Story Sq Ft | W3: 1/2 StoryVal/SqFt | X3: 1/2 Story % Base | Y3: 2nd Story Value | Z3: 2nd Sty Sq Ft | AA3: 2ndStyVal/Sqft | AB3: 2nd Story % Base | AC3: Att Gar Value | AD3: Att Gar Sq Ft | AE3: AttGarVal/SqFt | AF3: Att Gar % Base | AG3: Porch Value | AH3: Porch Sq Ft | AI3: PorchVal/SqFt | AJ3: Porch % Base | AK3: Cov Porch Value | AL3: Cov Porch Sq Ft | AM3: CovPrVal/SqFt | AN3: Cov Porch % Base | AO3: Deck Value | AP3: Deck Sq Ft | AQ3: DeckVal/SqFt | AR3: Deck % Base | AS3: Cov Deck Value | AT3: CovDeck Sq Ft | AU3: CovDeckVal/SqFt | AV3: CovDeck % Base | AW3: CarP Value | AX3: CarP Sq Ft | AY3: CarPVal/SqFt | AZ3: CarP % Base | BA3: EFP Value | BB3: EFP Sq Ft | BC3: EFPVal/SqFt | BD3: EFP % Base
A4: Chp | B4: 70380 | C4: =B4/F1 -> 49.424157 | D4: 1525 | E4: 0 | F4: 0 | G4: =E4/F4 -> #DIV/0! | H4: =G4/C4 -> #DIV/0! | I4: 0 | J4: 0 | K4: =I4/J4 -> #DIV/0! | L4: =K4/C4 -> #DIV/0! | M4: 21270 | N4: 672 | O4: =M4/N4 -> 31.651786 | P4: =O4/C4 -> 0.64041124 | Q4: 0 | R4: 0 | S4: =Q4/R4 -> #DIV/0! | T4: =S4/C4 -> #DIV/0! | U4: 0 | V4: 0 | W4: =U4/V4 -> #DIV/0! | X4: =W4/C4 -> #DIV/0! | Y4: 0 | Z4: 0 | AA4: =Y4/Z4 -> #DIV/0! | AB4: =AA4/C4 -> #DIV/0! | AC4: 7860 | AD4: 528 | AE4: =AC4/AD4 -> 14.886364 | AF4: =AE4/C4 -> 0.3011961 | AG4: 0 | AH4: 0 | AI4: =AG4/AH4 -> #DIV/0! | AJ4: =AI4/C4 -> #DIV/0! | AK4: 0 | AL4: 0 | AM4: =AK4/AL4 -> #DIV/0! | AN4: =AM4/C4 -> #DIV/0! | AO4: 0 | AP4: 0 | AQ4: =AO4/AP4 -> #DIV/0! | AR4: =AQ4/C4 -> #DIV/0! | AS4: 1860 | AT4: 120 | AU4: =AS4/AT4 -> 15.5 | AV4: =AU4/C4 -> 0.31361182 | AW4: 0 | AX4: 0 | AY4: =AW4/AX4 -> #DIV/0! | AZ4: =AY4/C4 -> #DIV/0! | BA4: 0 | BB4: 0 | BC4: =BA4/BB4 -> #DIV/0! | BD4: =BC4/C4 -> #DIV/0!
A5: Low | B5: 82800 | C5: =B5/F1 -> 58.146067 | D5: 1525 | E5: 0 | F5: 0 | G5: =E5/F5 -> #DIV/0! | H5: =G5/C5 -> #DIV/0! | I5: 0 | J5: 0 | K5: =I5/J5 -> #DIV/0! | L5: =K5/C5 -> #DIV/0! | M5: 26510 | N5: 672 | O5: =M5/N5 -> 39.449405 | P5: =O5/C5 -> 0.67845353 | Q5: 0 | R5: 0 | S5: =Q5/R5 -> #DIV/0! | T5: =S5/C5 -> #DIV/0! | U5: 0 | V5: 0 | W5: =U5/V5 -> #DIV/0! | X5: =W5/C5 -> #DIV/0! | Y5: 0 | Z5: 0 | AA5: =Y5/Z5 -> #DIV/0! | AB5: =AA5/C5 -> #DIV/0! | AC5: 10750 | AD5: 528 | AE5: =AC5/AD5 -> 20.359848 | AF5: =AE5/C5 -> 0.35015005 | AG5: 0 | AH5: 0 | AI5: =AG5/AH5 -> #DIV/0! | AJ5: =AI5/C5 -> #DIV/0! | AK5: 0 | AL5: 0 | AM5: =AK5/AL5 -> #DIV/0! | AN5: =AM5/C5 -> #DIV/0! | AO5: 0 | AP5: 0 | AQ5: =AO5/AP5 -> #DIV/0! | AR5: =AQ5/C5 -> #DIV/0! | AS5: 2640 | AT5: 120 | AU5: =AS5/AT5 -> 22 | AV5: =AU5/C5 -> 0.37835749 | AW5: 0 | AX5: 0 | AY5: =AW5/AX5 -> #DIV/0! | AZ5: =AY5/C5 -> #DIV/0! | BA5: 0 | BB5: 0 | BC5: =BA5/BB5 -> #DIV/0! | BD5: =BC5/C5 -> #DIV/0!
A6: Fair | B6: 96770 | C6: =B6/F1 -> 67.956461 | D6: 2100 | E6: 0 | F6: 0 | G6: =E6/F6 -> #DIV/0! | H6: =G6/C6 -> #DIV/0! | I6: 0 | J6: 0 | K6: =I6/J6 -> #DIV/0! | L6: =K6/C6 -> #DIV/0! | M6: 30290 | N6: 672 | O6: =M6/N6 -> 45.074405 | P6: =O6/C6 -> 0.66328358 | Q6: 0 | R6: 0 | S6: =Q6/R6 -> #DIV/0! | T6: =S6/C6 -> #DIV/0! | U6: 0 | V6: 0 | W6: =U6/V6 -> #DIV/0! | X6: =W6/C6 -> #DIV/0! | Y6: 0 | Z6: 0 | AA6: =Y6/Z6 -> #DIV/0! | AB6: =AA6/C6 -> #DIV/0! | AC6: 13350 | AD6: 528 | AE6: =AC6/AD6 -> 25.284091 | AF6: =AE6/C6 -> 0.37206309 | AG6: 0 | AH6: 0 | AI6: =AG6/AH6 -> #DIV/0! | AJ6: =AI6/C6 -> #DIV/0! | AK6: 0 | AL6: 0 | AM6: =AK6/AL6 -> #DIV/0! | AN6: =AM6/C6 -> #DIV/0! | AO6: 0 | AP6: 0 | AQ6: =AO6/AP6 -> #DIV/0! | AR6: =AQ6/C6 -> #DIV/0! | AS6: 2930 | AT6: 120 | AU6: =AS6/AT6 -> 24.416667 | AV6: =AU6/C6 -> 0.35929868 | AW6: 0 | AX6: 0 | AY6: =AW6/AX6 -> #DIV/0! | AZ6: =AY6/C6 -> #DIV/0! | BA6: 0 | BB6: 0 | BC6: =BA6/BB6 -> #DIV/0! | BD6: =BC6/C6 -> #DIV/0!
A7: Avg | B7: 117080 | C7: =B7/F1 -> 82.219101 | D7: 2700 | E7: 0 | F7: 0 | G7: =E7/F7 -> #DIV/0! | H7: =G7/C7 -> #DIV/0! | I7: 0 | J7: 0 | K7: =I7/J7 -> #DIV/0! | L7: =K7/C7 -> #DIV/0! | M7: 34770 | N7: 672 | O7: =M7/N7 -> 51.741071 | P7: =O7/C7 -> 0.62930719 | Q7: 0 | R7: 0 | S7: =Q7/R7 -> #DIV/0! | T7: =S7/C7 -> #DIV/0! | U7: 0 | V7: 0 | W7: =U7/V7 -> #DIV/0! | X7: =W7/C7 -> #DIV/0! | Y7: 0 | Z7: 0 | AA7: =Y7/Z7 -> #DIV/0! | AB7: =AA7/C7 -> #DIV/0! | AC7: 14170 | AD7: 528 | AE7: =AC7/AD7 -> 26.837121 | AF7: =AE7/C7 -> 0.32640981 | AG7: 0 | AH7: 0 | AI7: =AG7/AH7 -> #DIV/0! | AJ7: =AI7/C7 -> #DIV/0! | AK7: 0 | AL7: 0 | AM7: =AK7/AL7 -> #DIV/0! | AN7: =AM7/C7 -> #DIV/0! | AO7: 0 | AP7: 0 | AQ7: =AO7/AP7 -> #DIV/0! | AR7: =AQ7/C7 -> #DIV/0! | AS7: 3470 | AT7: 120 | AU7: =AS7/AT7 -> 28.916667 | AV7: =AU7/C7 -> 0.35170254 | AW7: 0 | AX7: 0 | AY7: =AW7/AX7 -> #DIV/0! | AZ7: =AY7/C7 -> #DIV/0! | BA7: 0 | BB7: 0 | BC7: =BA7/BB7 -> #DIV/0! | BD7: =BC7/C7 -> #DIV/0!
A8: Good | B8: 145500 | C8: =B8/F1 -> 102.17697 | D8: 5250 | E8: 0 | F8: 0 | G8: =E8/F8 -> #DIV/0! | H8: =G8/C8 -> #DIV/0! | I8: 0 | J8: 0 | K8: =I8/J8 -> #DIV/0! | L8: =K8/C8 -> #DIV/0! | M8: 47650 | N8: 672 | O8: =M8/N8 -> 70.907738 | P8: =O8/C8 -> 0.69396989 | Q8: 0 | R8: 0 | S8: =Q8/R8 -> #DIV/0! | T8: =S8/C8 -> #DIV/0! | U8: 0 | V8: 0 | W8: =U8/V8 -> #DIV/0! | X8: =W8/C8 -> #DIV/0! | Y8: 0 | Z8: 0 | AA8: =Y8/Z8 -> #DIV/0! | AB8: =AA8/C8 -> #DIV/0! | AC8: 16150 | AD8: 528 | AE8: =AC8/AD8 -> 30.587121 | AF8: =AE8/C8 -> 0.29935437 | AG8: 0 | AH8: 0 | AI8: =AG8/AH8 -> #DIV/0! | AJ8: =AI8/C8 -> #DIV/0! | AK8: 0 | AL8: 0 | AM8: =AK8/AL8 -> #DIV/0! | AN8: =AM8/C8 -> #DIV/0! | AO8: 0 | AP8: 0 | AQ8: =AO8/AP8 -> #DIV/0! | AR8: =AQ8/C8 -> #DIV/0! | AS8: 4110 | AT8: 120 | AU8: =AS8/AT8 -> 34.25 | AV8: =AU8/C8 -> 0.33520275 | AW8: 0 | AX8: 0 | AY8: =AW8/AX8 -> #DIV/0! | AZ8: =AY8/C8 -> #DIV/0! | BA8: 0 | BB8: 0 | BC8: =BA8/BB8 -> #DIV/0! | BD8: =BC8/C8 -> #DIV/0!
A9: VGood | B9: 192270 | C9: =B9/F1 -> 135.02107 | D9: 7050 | E9: 0 | F9: 0 | G9: =E9/F9 -> #DIV/0! | H9: =G9/C9 -> #DIV/0! | I9: 0 | J9: 0 | K9: =I9/J9 -> #DIV/0! | L9: =K9/C9 -> #DIV/0! | M9: 52700 | N9: 672 | O9: =M9/N9 -> 78.422619 | P9: =O9/C9 -> 0.58081765 | Q9: 0 | R9: 0 | S9: =Q9/R9 -> #DIV/0! | T9: =S9/C9 -> #DIV/0! | U9: 0 | V9: 0 | W9: =U9/V9 -> #DIV/0! | X9: =W9/C9 -> #DIV/0! | Y9: 0 | Z9: 0 | AA9: =Y9/Z9 -> #DIV/0! | AB9: =AA9/C9 -> #DIV/0! | AC9: 18200 | AD9: 528 | AE9: =AC9/AD9 -> 34.469697 | AF9: =AE9/C9 -> 0.25529125 | AG9: 0 | AH9: 0 | AI9: =AG9/AH9 -> #DIV/0! | AJ9: =AI9/C9 -> #DIV/0! | AK9: 0 | AL9: 0 | AM9: =AK9/AL9 -> #DIV/0! | AN9: =AM9/C9 -> #DIV/0! | AO9: 0 | AP9: 0 | AQ9: =AO9/AP9 -> #DIV/0! | AR9: =AQ9/C9 -> #DIV/0! | AS9: 4780 | AT9: 120 | AU9: =AS9/AT9 -> 39.833333 | AV9: =AU9/C9 -> 0.29501569 | AW9: 0 | AX9: 0 | AY9: =AW9/AX9 -> #DIV/0! | AZ9: =AY9/C9 -> #DIV/0! | BA9: 0 | BB9: 0 | BC9: =BA9/BB9 -> #DIV/0! | BD9: =BC9/C9 -> #DIV/0!
A10: Excellent | B10: 232940 | C10: =B10/F1 -> 163.58146 | D10: 10950 | E10: 0 | F10: 0 | G10: =E10/F10 -> #DIV/0! | H10: =G10/C10 -> #DIV/0! | I10: 0 | J10: 0 | K10: =I10/J10 -> #DIV/0! | L10: =K10/C10 -> #DIV/0! | M10: 63320 | N10: 672 | O10: =M10/N10 -> 94.22619 | P10: =O10/C10 -> 0.57601998 | Q10: 0 | R10: 0 | S10: =Q10/R10 -> #DIV/0! | T10: =S10/C10 -> #DIV/0! | U10: 0 | V10: 0 | W10: =U10/V10 -> #DIV/0! | X10: =W10/C10 -> #DIV/0! | Y10: 0 | Z10: 0 | AA10: =Y10/Z10 -> #DIV/0! | AB10: =AA10/C10 -> #DIV/0! | AC10: 26050 | AD10: 528 | AE10: =AC10/AD10 -> 49.337121 | AF10: =AE10/C10 -> 0.30160582 | AG10: 0 | AH10: 0 | AI10: =AG10/AH10 -> #DIV/0! | AJ10: =AI10/C10 -> #DIV/0! | AK10: 0 | AL10: 0 | AM10: =AK10/AL10 -> #DIV/0! | AN10: =AM10/C10 -> #DIV/0! | AO10: 0 | AP10: 0 | AQ10: =AO10/AP10 -> #DIV/0! | AR10: =AQ10/C10 -> #DIV/0! | AS10: 5430 | AT10: 120 | AU10: =AS10/AT10 -> 45.25 | AV10: =AU10/C10 -> 0.27662059 | AW10: 0 | AX10: 0 | AY10: =AW10/AX10 -> #DIV/0! | AZ10: =AY10/C10 -> #DIV/0! | BA10: 0 | BB10: 0 | BC10: =BA10/BB10 -> #DIV/0! | BD10: =BC10/C10 -> #DIV/0!
C11: =AVERAGE(Table1[MA $/Sq Ft]) -> 94.07504 | D11: =AVERAGE(Table1[Basic Allowance]) -> 4442.8571 | H11: =AVERAGE(Table1[Bsmt % Base]) -> #DIV/0! | L11: =AVERAGE(Table1[[#Headers],[#Data],[UnfBsmt % Base]]) -> #DIV/0! | M11: =AVERAGE(Table1[Lower Value]) -> 39501.429 | O11: =AVERAGE(Table1[LowerVal/SqFt]) -> 58.781888 | P11: =AVERAGE(Table1[Lower % Base]) -> 0.63746615 | T11: =AVERAGE(Table1[Unf Lower % Base]) -> #DIV/0! | X11: =AVERAGE(Table1[1/2 Story % Base]) -> #DIV/0! | AB11: =AVERAGE(Table1[2nd Story % Base]) -> #DIV/0! | AC11: =SUBTOTAL(101,Table1[Att Gar Value]) -> 15218.571 | AE11: =AVERAGE(Table1[AttGarVal/SqFt]) -> 28.823052 | AF11: =AVERAGE(Table1[Att Gar % Base]) -> 0.31515293 | AJ11: =AVERAGE(Table1[Porch % Base]) -> #DIV/0! | AN11: =AVERAGE(Table1[Cov Porch % Base]) -> #DIV/0! | AR11: =AVERAGE(Table1[Deck % Base]) -> #DIV/0! | AS11: =SUBTOTAL(101,Table1[Cov Deck Value]) -> 3602.8571 | AU11: =AVERAGE(Table1[CovDeckVal/SqFt]) -> 30.02381 | AV11: =AVERAGE(Table1[CovDeck % Base]) -> 0.32997279 | AZ11: =AVERAGE(Table1[CarP % Base]) -> #DIV/0! | BD11: =AVERAGE(Table1[EFP % Base]) -> #DIV/0!
B13: Parcel ID: 131953020000011 | E13: Main area sq ft: | F13: 1961 | H13: HT: 1 St | J13: Year Built: | K13: 1993
E14: Basement | I14: Unfinished Basement | M14: Lower | Q14: Unfinished Lower | U14: 1/2 Story | Y14: 2nd Story | AC14: Attached Garage | AG14: Porch | AK14: Covered Porch | AO14: Deck | AS14: Covered Deck | AW14: Carport | BA14: EFP/Sunroom
A15: Grade | B15: Main Area $ | C15: MA $/Sq Ft | D15: Basic Allowance | E15: BsmtVal | F15: Bsmt SqFt | G15: BsmtVal/Sq Ft | H15: Bsmt % Base | I15: UnfBsmtVal | J15: UnfBsmt Sq Ft | K15: UnfBsmtVal/SqFt | L15: UnfBsmt % Base | M15: Lower Value | N15: Lower Sq Ft | O15: LowerVal/SqFt | P15: Lower % Base | Q15: Unf Lower Value | R15: UnfLower Sq Ft | S15: UnfLowVal/SqFt2 | T15: Unf Lower % Base | U15: 1/2 Story Value | V15: 1/2 Story Sq Ft | W15: 1/2 StoryVal/SqFt | X15: 1/2 Story % Base | Y15: 2nd Story Value | Z15: 2nd Sty Sq Ft | AA15: 2ndStyVal/Sqft | AB15: 2nd Story % Base | AC15: Att Gar Value | AD15: Att Gar Sq Ft | AE15: AttGarVal/SqFt | AF15: Att Gar % Base | AG15: Porch Value | AH15: Porch Sq Ft | AI15: PorchVal/SqFt | AJ15: Porch % Base | AK15: Cov Porch Value | AL15: Cov Porch Sq Ft | AM15: CovPrVal/SqFt | AN15: Cov Porch % Base | AO15: Deck Value | AP15: Deck Sq Ft | AQ15: DeckVal/SqFt | AR15: Deck % Base | AS15: Cov Deck Value | AT15: CovDeck Sq Ft | AU15: CovDeckVal/SqFt | AV15: CovDeck % Base | AW15: CarP Value | AX15: CarP Sq Ft | AY15: CarPVal/SqFt | AZ15: CarP % Base | BA15: EFP Value | BB15: EFP Sq Ft | BC15: EFPVal/SqFt | BD15: EFP % Base
A16: Chp | B16: 92520 | C16: =B16/F13 -> 47.18001 | D16: 1525 | E16: 0 | F16: 0 | G16: =E16/F16 -> #DIV/0! | H16: =G16/C16 -> #DIV/0! | I16: 0 | J16: 0 | K16: =I16/J16 -> #DIV/0! | L16: =K16/C16 -> #DIV/0! | M16: 0 | N16: 0 | O16: =M16/N16 -> #DIV/0! | P16: =O16/C16 -> #DIV/0! | Q16: 0 | R16: 0 | S16: =Q16/R16 -> #DIV/0! | T16: =S16/C16 -> #DIV/0! | U16: 0 | V16: 0 | W16: =U16/V16 -> #DIV/0! | X16: =W16/C16 -> #DIV/0! | Y16: 0 | Z16: 0 | AA16: =Y16/Z16 -> #DIV/0! | AB16: =AA16/C16 -> #DIV/0! | AC16: 7750 | AD16: 519 | AE16: =AC16/AD16 -> 14.932563 | AF16: =AE16/C16 -> 0.31650189 | AG16: 0 | AH16: 0 | AI16: =AG16/AH16 -> #DIV/0! | AJ16: =AI16/C16 -> #DIV/0! | AK16: 1110 | AL16: 132 | AM16: =AK16/AL16 -> 8.4090909 | AN16: =AM16/C16 -> 0.17823419 | AO16: 0 | AP16: 0 | AQ16: =AO16/AP16 -> #DIV/0! | AR16: =AQ16/C16 -> #DIV/0! | AS16: 0 | AT16: 0 | AU16: =AS16/AT16 -> #DIV/0! | AV16: =AU16/C16 -> #DIV/0! | AW16: 0 | AX16: 0 | AY16: =AW16/AX16 -> #DIV/0! | AZ16: =AY16/C16 -> #DIV/0! | BA16: 0 | BB16: 0 | BC16: =BA16/BB16 -> #DIV/0! | BD16: =BC16/C16 -> #DIV/0!
A17: Low | B17: 108800 | C17: =B17/F13 -> 55.481897 | D17: 1525 | E17: 0 | F17: 0 | G17: =E17/F17 -> #DIV/0! | H17: =G17/C17 -> #DIV/0! | I17: 0 | J17: 0 | K17: =I17/J17 -> #DIV/0! | L17: =K17/C17 -> #DIV/0! | M17: 0 | N17: 0 | O17: =M17/N17 -> #DIV/0! | P17: =O17/C17 -> #DIV/0! | Q17: 0 | R17: 0 | S17: =Q17/R17 -> #DIV/0! | T17: =S17/C17 -> #DIV/0! | U17: 0 | V17: 0 | W17: =U17/V17 -> #DIV/0! | X17: =W17/C17 -> #DIV/0! | Y17: 0 | Z17: 0 | AA17: =Y17/Z17 -> #DIV/0! | AB17: =AA17/C17 -> #DIV/0! | AC17: 10610 | AD17: 519 | AE17: =AC17/AD17 -> 20.44316 | AF17: =AE17/C17 -> 0.36846541 | AG17: 0 | AH17: 0 | AI17: =AG17/AH17 -> #DIV/0! | AJ17: =AI17/C17 -> #DIV/0! | AK17: 1540 | AL17: 132 | AM17: =AK17/AL17 -> 11.666667 | AN17: =AM17/C17 -> 0.2102788 | AO17: 0 | AP17: 0 | AQ17: =AO17/AP17 -> #DIV/0! | AR17: =AQ17/C17 -> #DIV/0! | AS17: 0 | AT17: 0 | AU17: =AS17/AT17 -> #DIV/0! | AV17: =AU17/C17 -> #DIV/0! | AW17: 0 | AX17: 0 | AY17: =AW17/AX17 -> #DIV/0! | AZ17: =AY17/C17 -> #DIV/0! | BA17: 0 | BB17: 0 | BC17: =BA17/BB17 -> #DIV/0! | BD17: =BC17/C17 -> #DIV/0!
A18: Fair | B18: 126810 | C18: =B18/F13 -> 64.665987 | D18: 2100 | E18: 0 | F18: 0 | G18: =E18/F18 -> #DIV/0! | H18: =G18/C18 -> #DIV/0! | I18: 0 | J18: 0 | K18: =I18/J18 -> #DIV/0! | L18: =K18/C18 -> #DIV/0! | M18: 0 | N18: 0 | O18: =M18/N18 -> #DIV/0! | P18: =O18/C18 -> #DIV/0! | Q18: 0 | R18: 0 | S18: =Q18/R18 -> #DIV/0! | T18: =S18/C18 -> #DIV/0! | U18: 0 | V18: 0 | W18: =U18/V18 -> #DIV/0! | X18: =W18/C18 -> #DIV/0! | Y18: 0 | Z18: 0 | AA18: =Y18/Z18 -> #DIV/0! | AB18: =AA18/C18 -> #DIV/0! | AC18: 13140 | AD18: 519 | AE18: =AC18/AD18 -> 25.317919 | AF18: =AE18/C18 -> 0.39151833 | AG18: 0 | AH18: 0 | AI18: =AG18/AH18 -> #DIV/0! | AJ18: =AI18/C18 -> #DIV/0! | AK18: 1800 | AL18: 132 | AM18: =AK18/AL18 -> 13.636364 | AN18: =AM18/C18 -> 0.21087382 | AO18: 0 | AP18: 0 | AQ18: =AO18/AP18 -> #DIV/0! | AR18: =AQ18/C18 -> #DIV/0! | AS18: 0 | AT18: 0 | AU18: =AS18/AT18 -> #DIV/0! | AV18: =AU18/C18 -> #DIV/0! | AW18: 0 | AX18: 0 | AY18: =AW18/AX18 -> #DIV/0! | AZ18: =AY18/C18 -> #DIV/0! | BA18: 0 | BB18: 0 | BC18: =BA18/BB18 -> #DIV/0! | BD18: =BC18/C18 -> #DIV/0!
A19: Avg | B19: 155150 | C19: =B19/F13 -> 79.117797 | D19: 2700 | E19: 0 | F19: 0 | G19: =E19/F19 -> #DIV/0! | H19: =G19/C19 -> #DIV/0! | I19: 0 | J19: 0 | K19: =I19/J19 -> #DIV/0! | L19: =K19/C19 -> #DIV/0! | M19: 0 | N19: 0 | O19: =M19/N19 -> #DIV/0! | P19: =O19/C19 -> #DIV/0! | Q19: 0 | R19: 0 | S19: =Q19/R19 -> #DIV/0! | T19: =S19/C19 -> #DIV/0! | U19: 0 | V19: 0 | W19: =U19/V19 -> #DIV/0! | X19: =W19/C19 -> #DIV/0! | Y19: 0 | Z19: 0 | AA19: =Y19/Z19 -> #DIV/0! | AB19: =AA19/C19 -> #DIV/0! | AC19: 13950 | AD19: 519 | AE19: =AC19/AD19 -> 26.878613 | AF19: =AE19/C19 -> 0.33972903 | AG19: 0 | AH19: 0 | AI19: =AG19/AH19 -> #DIV/0! | AJ19: =AI19/C19 -> #DIV/0! | AK19: 2350 | AL19: 132 | AM19: =AK19/AL19 -> 17.80303 | AN19: =AM19/C19 -> 0.22501929 | AO19: 0 | AP19: 0 | AQ19: =AO19/AP19 -> #DIV/0! | AR19: =AQ19/C19 -> #DIV/0! | AS19: 0 | AT19: 0 | AU19: =AS19/AT19 -> #DIV/0! | AV19: =AU19/C19 -> #DIV/0! | AW19: 0 | AX19: 0 | AY19: =AW19/AX19 -> #DIV/0! | AZ19: =AY19/C19 -> #DIV/0! | BA19: 0 | BB19: 0 | BC19: =BA19/BB19 -> #DIV/0! | BD19: =BC19/C19 -> #DIV/0!
A20: Good | B20: 191770 | C20: =B20/F13 -> 97.791943 | D20: 5250 | E20: 0 | F20: 0 | G20: =E20/F20 -> #DIV/0! | H20: =G20/C20 -> #DIV/0! | I20: 0 | J20: 0 | K20: =I20/J20 -> #DIV/0! | L20: =K20/C20 -> #DIV/0! | M20: 0 | N20: 0 | O20: =M20/N20 -> #DIV/0! | P20: =O20/C20 -> #DIV/0! | Q20: 0 | R20: 0 | S20: =Q20/R20 -> #DIV/0! | T20: =S20/C20 -> #DIV/0! | U20: 0 | V20: 0 | W20: =U20/V20 -> #DIV/0! | X20: =W20/C20 -> #DIV/0! | Y20: 0 | Z20: 0 | AA20: =Y20/Z20 -> #DIV/0! | AB20: =AA20/C20 -> #DIV/0! | AC20: 15890 | AD20: 519 | AE20: =AC20/AD20 -> 30.61657 | AF20: =AE20/C20 -> 0.31307866 | AG20: 0 | AH20: 0 | AI20: =AG20/AH20 -> #DIV/0! | AJ20: =AI20/C20 -> #DIV/0! | AK20: 2580 | AL20: 132 | AM20: =AK20/AL20 -> 19.545455 | AN20: =AM20/C20 -> 0.19986774 | AO20: 0 | AP20: 0 | AQ20: =AO20/AP20 -> #DIV/0! | AR20: =AQ20/C20 -> #DIV/0! | AS20: 0 | AT20: 0 | AU20: =AS20/AT20 -> #DIV/0! | AV20: =AU20/C20 -> #DIV/0! | AW20: 0 | AX20: 0 | AY20: =AW20/AX20 -> #DIV/0! | AZ20: =AY20/C20 -> #DIV/0! | BA20: 0 | BB20: 0 | BC20: =BA20/BB20 -> #DIV/0! | BD20: =BC20/C20 -> #DIV/0!
A21: VGood | B21: 255900 | C21: =B21/F13 -> 130.49465 | D21: 7050 | E21: 0 | F21: 0 | G21: =E21/F21 -> #DIV/0! | H21: =G21/C21 -> #DIV/0! | I21: 0 | J21: 0 | K21: =I21/J21 -> #DIV/0! | L21: =K21/C21 -> #DIV/0! | M21: 0 | N21: 0 | O21: =M21/N21 -> #DIV/0! | P21: =O21/C21 -> #DIV/0! | Q21: 0 | R21: 0 | S21: =Q21/R21 -> #DIV/0! | T21: =S21/C21 -> #DIV/0! | U21: 0 | V21: 0 | W21: =U21/V21 -> #DIV/0! | X21: =W21/C21 -> #DIV/0! | Y21: 0 | Z21: 0 | AA21: =Y21/Z21 -> #DIV/0! | AB21: =AA21/C21 -> #DIV/0! | AC21: 17940 | AD21: 519 | AE21: =AC21/AD21 -> 34.566474 | AF21: =AE21/C21 -> 0.26488806 | AG21: 0 | AH21: 0 | AI21: =AG21/AH21 -> #DIV/0! | AJ21: =AI21/C21 -> #DIV/0! | AK21: 3160 | AL21: 132 | AM21: =AK21/AL21 -> 23.939394 | AN21: =AM21/C21 -> 0.18345116 | AO21: 0 | AP21: 0 | AQ21: =AO21/AP21 -> #DIV/0! | AR21: =AQ21/C21 -> #DIV/0! | AS21: 0 | AT21: 0 | AU21: =AS21/AT21 -> #DIV/0! | AV21: =AU21/C21 -> #DIV/0! | AW21: 0 | AX21: 0 | AY21: =AW21/AX21 -> #DIV/0! | AZ21: =AY21/C21 -> #DIV/0! | BA21: 0 | BB21: 0 | BC21: =BA21/BB21 -> #DIV/0! | BD21: =BC21/C21 -> #DIV/0!
A22: Excellent | B22: 309790 | C22: =B22/F13 -> 157.97552 | D22: 10950 | E22: 0 | F22: 0 | G22: =E22/F22 -> #DIV/0! | H22: =G22/C22 -> #DIV/0! | I22: 0 | J22: 0 | K22: =I22/J22 -> #DIV/0! | L22: =K22/C22 -> #DIV/0! | M22: 0 | N22: 0 | O22: =M22/N22 -> #DIV/0! | P22: =O22/C22 -> #DIV/0! | Q22: 0 | R22: 0 | S22: =Q22/R22 -> #DIV/0! | T22: =S22/C22 -> #DIV/0! | U22: 0 | V22: 0 | W22: =U22/V22 -> #DIV/0! | X22: =W22/C22 -> #DIV/0! | Y22: 0 | Z22: 0 | AA22: =Y22/Z22 -> #DIV/0! | AB22: =AA22/C22 -> #DIV/0! | AC22: 25670 | AD22: 519 | AE22: =AC22/AD22 -> 49.460501 | AF22: =AE22/C22 -> 0.31308965 | AG22: 0 | AH22: 0 | AI22: =AG22/AH22 -> #DIV/0! | AJ22: =AI22/C22 -> #DIV/0! | AK22: 3830 | AL22: 132 | AM22: =AK22/AL22 -> 29.015152 | AN22: =AM22/C22 -> 0.18366865 | AO22: 0 | AP22: 0 | AQ22: =AO22/AP22 -> #DIV/0! | AR22: =AQ22/C22 -> #DIV/0! | AS22: 0 | AT22: 0 | AU22: =AS22/AT22 -> #DIV/0! | AV22: =AU22/C22 -> #DIV/0! | AW22: 0 | AX22: 0 | AY22: =AW22/AX22 -> #DIV/0! | AZ22: =AY22/C22 -> #DIV/0! | BA22: 0 | BB22: 0 | BC22: =BA22/BB22 -> #DIV/0! | BD22: =BC22/C22 -> #DIV/0!
C23: =AVERAGE(Table11011[MA $/Sq Ft]) -> 90.386829 | D23: =AVERAGE(Table11011[Basic Allowance]) -> 4442.8571 | H23: =AVERAGE(Table11011[Bsmt % Base]) -> #DIV/0! | L23: =AVERAGE(Table11011[[#Headers],[#Data],[UnfBsmt % Base]]) -> #DIV/0! | O23: =AVERAGE(Table11011[LowerVal/SqFt]) -> #DIV/0! | P23: =AVERAGE(Table11011[Lower % Base]) -> #DIV/0! | T23: =AVERAGE(Table11011[Unf Lower % Base]) -> #DIV/0! | X23: =AVERAGE(Table11011[1/2 Story % Base]) -> #DIV/0! | AB23: =AVERAGE(Table11011[2nd Story % Base]) -> #DIV/0! | AC23: =SUBTOTAL(101,Table11011[Att Gar Value]) -> 14992.857 | AE23: =AVERAGE(Table11011[AttGarVal/SqFt]) -> 28.887971 | AF23: =AVERAGE(Table11011[Att Gar % Base]) -> 0.32961015 | AJ23: =AVERAGE(Table11011[Porch % Base]) -> #DIV/0! | AN23: =AVERAGE(Table11011[Cov Porch % Base]) -> 0.19877052 | AR23: =AVERAGE(Table11011[Deck % Base]) -> #DIV/0! | AU23: =AVERAGE(Table11011[CovDeckVal/SqFt]) -> #DIV/0! | AV23: =AVERAGE(Table11011[CovDeck % Base]) -> #DIV/0! | AZ23: =AVERAGE(Table11011[CarP % Base]) -> #DIV/0! | BD23: =AVERAGE(Table11011[EFP % Base]) -> #DIV/0!
B25: Parcel ID: 110892040006010 | E25: Main area sq ft: | F25: 2082 | H25: HT: 1 St | J25: Year Built: | K25: 1976
E26: Basement | I26: Unfinished Basement | M26: Lower | Q26: Unfinished Lower | U26: 1/2 Story | Y26: 2nd Story | AC26: Attached Garage | AG26: Porch | AK26: Covered Porch | AO26: Deck | AS26: Covered Deck | AW26: Carport | BA26: EFP/Sunroom
A27: Grade | B27: Main Area $ | C27: MA $/Sq Ft | D27: Basic Allowance | E27: BsmtVal | F27: Bsmt SqFt | G27: BsmtVal/Sq Ft | H27: Bsmt % Base | I27: UnfBsmtVal | J27: UnfBsmt Sq Ft | K27: UnfBsmtVal/SqFt | L27: UnfBsmt % Base | M27: Lower Value | N27: Lower Sq Ft | O27: LowerVal/SqFt | P27: Lower % Base | Q27: Unf Lower Value | R27: UnfLower Sq Ft | S27: UnfLowVal/SqFt2 | T27: Unf Lower % Base | U27: 1/2 Story Value | V27: 1/2 Story Sq Ft | W27: 1/2 StoryVal/SqFt | X27: 1/2 Story % Base | Y27: 2nd Story Value | Z27: 2nd Sty Sq Ft | AA27: 2ndStyVal/Sqft | AB27: 2nd Story % Base | AC27: Att Gar Value | AD27: Att Gar Sq Ft | AE27: AttGarVal/SqFt | AF27: Att Gar % Base | AG27: Porch Value | AH27: Porch Sq Ft | AI27: PorchVal/SqFt | AJ27: Porch % Base | AK27: Cov Porch Value | AL27: Cov Porch Sq Ft | AM27: CovPrVal/SqFt | AN27: Cov Porch % Base | AO27: Deck Value | AP27: Deck Sq Ft | AQ27: DeckVal/SqFt | AR27: Deck % Base | AS27: Cov Deck Value | AT27: CovDeck Sq Ft | AU27: CovDeckVal/SqFt | AV27: CovDeck % Base | AW27: CarP Value | AX27: CarP Sq Ft | AY27: CarPVal/SqFt | AZ27: CarP % Base | BA27: EFP Value | BB27: EFP Sq Ft | BC27: EFPVal/SqFt | BD27: EFP % Base
A28: Chp | B28: 97030 | C28: =B28/F25 -> 46.604227 | D28: 1525 | E28: 0 | F28: 0 | G28: =E28/F28 -> #DIV/0! | H28: =G28/C28 -> #DIV/0! | I28: 0 | J28: 0 | K28: =I28/J28 -> #DIV/0! | L28: =K28/C28 -> #DIV/0! | M28: 0 | N28: 0 | O28: =M28/N28 -> #DIV/0! | P28: =O28/C28 -> #DIV/0! | Q28: 0 | R28: 0 | S28: =Q28/R28 -> #DIV/0! | T28: =S28/C28 -> #DIV/0! | U28: 0 | V28: 0 | W28: =U28/V28 -> #DIV/0! | X28: =W28/C28 -> #DIV/0! | Y28: 0 | Z28: 0 | AA28: =Y28/Z28 -> #DIV/0! | AB28: =AA28/C28 -> #DIV/0! | AC28: 8160 | AD28: 552 | AE28: =AC28/AD28 -> 14.782609 | AF28: =AE28/C28 -> 0.31719459 | AG28: 0 | AH28: 0 | AI28: =AG28/AH28 -> #DIV/0! | AJ28: =AI28/C28 -> #DIV/0! | AK28: 0 | AL28: 0 | AM28: =AK28/AL28 -> #DIV/0! | AN28: =AM28/C28 -> #DIV/0! | AO28: 0 | AP28: 0 | AQ28: =AO28/AP28 -> #DIV/0! | AR28: =AQ28/C28 -> #DIV/0! | AS28: 0 | AT28: 0 | AU28: =AS28/AT28 -> #DIV/0! | AV28: =AU28/C28 -> #DIV/0! | AW28: 0 | AX28: 0 | AY28: =AW28/AX28 -> #DIV/0! | AZ28: =AY28/C28 -> #DIV/0! | BA28: 0 | BB28: 0 | BC28: =BA28/BB28 -> #DIV/0! | BD28: =BC28/C28 -> #DIV/0!
A29: Low | B29: 114090 | C29: =B29/F25 -> 54.798271 | D29: 1525 | E29: 0 | F29: 0 | G29: =E29/F29 -> #DIV/0! | H29: =G29/C29 -> #DIV/0! | I29: 0 | J29: 0 | K29: =I29/J29 -> #DIV/0! | L29: =K29/C29 -> #DIV/0! | M29: 0 | N29: 0 | O29: =M29/N29 -> #DIV/0! | P29: =O29/C29 -> #DIV/0! | Q29: 0 | R29: 0 | S29: =Q29/R29 -> #DIV/0! | T29: =S29/C29 -> #DIV/0! | U29: 0 | V29: 0 | W29: =U29/V29 -> #DIV/0! | X29: =W29/C29 -> #DIV/0! | Y29: 0 | Z29: 0 | AA29: =Y29/Z29 -> #DIV/0! | AB29: =AA29/C29 -> #DIV/0! | AC29: 11110 | AD29: 552 | AE29: =AC29/AD29 -> 20.126812 | AF29: =AE29/C29 -> 0.36728917 | AG29: 0 | AH29: 0 | AI29: =AG29/AH29 -> #DIV/0! | AJ29: =AI29/C29 -> #DIV/0! | AK29: 0 | AL29: 0 | AM29: =AK29/AL29 -> #DIV/0! | AN29: =AM29/C29 -> #DIV/0! | AO29: 0 | AP29: 0 | AQ29: =AO29/AP29 -> #DIV/0! | AR29: =AQ29/C29 -> #DIV/0! | AS29: 0 | AT29: 0 | AU29: =AS29/AT29 -> #DIV/0! | AV29: =AU29/C29 -> #DIV/0! | AW29: 0 | AX29: 0 | AY29: =AW29/AX29 -> #DIV/0! | AZ29: =AY29/C29 -> #DIV/0! | BA29: 0 | BB29: 0 | BC29: =BA29/BB29 -> #DIV/0! | BD29: =BC29/C29 -> #DIV/0!
A30: Fair | B30: 132880 | C30: =B30/F25 -> 63.823247 | D30: 2100 | E30: 0 | F30: 0 | G30: =E30/F30 -> #DIV/0! | H30: =G30/C30 -> #DIV/0! | I30: 0 | J30: 0 | K30: =I30/J30 -> #DIV/0! | L30: =K30/C30 -> #DIV/0! | M30: 0 | N30: 0 | O30: =M30/N30 -> #DIV/0! | P30: =O30/C30 -> #DIV/0! | Q30: 0 | R30: 0 | S30: =Q30/R30 -> #DIV/0! | T30: =S30/C30 -> #DIV/0! | U30: 0 | V30: 0 | W30: =U30/V30 -> #DIV/0! | X30: =W30/C30 -> #DIV/0! | Y30: 0 | Z30: 0 | AA30: =Y30/Z30 -> #DIV/0! | AB30: =AA30/C30 -> #DIV/0! | AC30: 13900 | AD30: 552 | AE30: =AC30/AD30 -> 25.181159 | AF30: =AE30/C30 -> 0.39454526 | AG30: 0 | AH30: 0 | AI30: =AG30/AH30 -> #DIV/0! | AJ30: =AI30/C30 -> #DIV/0! | AK30: 0 | AL30: 0 | AM30: =AK30/AL30 -> #DIV/0! | AN30: =AM30/C30 -> #DIV/0! | AO30: 0 | AP30: 0 | AQ30: =AO30/AP30 -> #DIV/0! | AR30: =AQ30/C30 -> #DIV/0! | AS30: 0 | AT30: 0 | AU30: =AS30/AT30 -> #DIV/0! | AV30: =AU30/C30 -> #DIV/0! | AW30: 0 | AX30: 0 | AY30: =AW30/AX30 -> #DIV/0! | AZ30: =AY30/C30 -> #DIV/0! | BA30: 0 | BB30: 0 | BC30: =BA30/BB30 -> #DIV/0! | BD30: =BC30/C30 -> #DIV/0!
A31: Avg | B31: 163830 | C31: =B31/F25 -> 78.688761 | D31: 2700 | E31: 0 | F31: 0 | G31: =E31/F31 -> #DIV/0! | H31: =G31/C31 -> #DIV/0! | I31: 0 | J31: 0 | K31: =I31/J31 -> #DIV/0! | L31: =K31/C31 -> #DIV/0! | M31: 0 | N31: 0 | O31: =M31/N31 -> #DIV/0! | P31: =O31/C31 -> #DIV/0! | Q31: 0 | R31: 0 | S31: =Q31/R31 -> #DIV/0! | T31: =S31/C31 -> #DIV/0! | U31: 0 | V31: 0 | W31: =U31/V31 -> #DIV/0! | X31: =W31/C31 -> #DIV/0! | Y31: 0 | Z31: 0 | AA31: =Y31/Z31 -> #DIV/0! | AB31: =AA31/C31 -> #DIV/0! | AC31: 14770 | AD31: 552 | AE31: =AC31/AD31 -> 26.757246 | AF31: =AE31/C31 -> 0.34003899 | AG31: 0 | AH31: 0 | AI31: =AG31/AH31 -> #DIV/0! | AJ31: =AI31/C31 -> #DIV/0! | AK31: 0 | AL31: 0 | AM31: =AK31/AL31 -> #DIV/0! | AN31: =AM31/C31 -> #DIV/0! | AO31: 0 | AP31: 0 | AQ31: =AO31/AP31 -> #DIV/0! | AR31: =AQ31/C31 -> #DIV/0! | AS31: 0 | AT31: 0 | AU31: =AS31/AT31 -> #DIV/0! | AV31: =AU31/C31 -> #DIV/0! | AW31: 0 | AX31: 0 | AY31: =AW31/AX31 -> #DIV/0! | AZ31: =AY31/C31 -> #DIV/0! | BA31: 0 | BB31: 0 | BC31: =BA31/BB31 -> #DIV/0! | BD31: =BC31/C31 -> #DIV/0!
A32: Good | B32: 202360 | C32: =B32/F25 -> 97.195005 | D32: 5250 | E32: 0 | F32: 0 | G32: =E32/F32 -> #DIV/0! | H32: =G32/C32 -> #DIV/0! | I32: 0 | J32: 0 | K32: =I32/J32 -> #DIV/0! | L32: =K32/C32 -> #DIV/0! | M32: 0 | N32: 0 | O32: =M32/N32 -> #DIV/0! | P32: =O32/C32 -> #DIV/0! | Q32: 0 | R32: 0 | S32: =Q32/R32 -> #DIV/0! | T32: =S32/C32 -> #DIV/0! | U32: 0 | V32: 0 | W32: =U32/V32 -> #DIV/0! | X32: =W32/C32 -> #DIV/0! | Y32: 0 | Z32: 0 | AA32: =Y32/Z32 -> #DIV/0! | AB32: =AA32/C32 -> #DIV/0! | AC32: 16820 | AD32: 552 | AE32: =AC32/AD32 -> 30.471014 | AF32: =AE32/C32 -> 0.31350391 | AG32: 0 | AH32: 0 | AI32: =AG32/AH32 -> #DIV/0! | AJ32: =AI32/C32 -> #DIV/0! | AK32: 0 | AL32: 0 | AM32: =AK32/AL32 -> #DIV/0! | AN32: =AM32/C32 -> #DIV/0! | AO32: 0 | AP32: 0 | AQ32: =AO32/AP32 -> #DIV/0! | AR32: =AQ32/C32 -> #DIV/0! | AS32: 0 | AT32: 0 | AU32: =AS32/AT32 -> #DIV/0! | AV32: =AU32/C32 -> #DIV/0! | AW32: 0 | AX32: 0 | AY32: =AW32/AX32 -> #DIV/0! | AZ32: =AY32/C32 -> #DIV/0! | BA32: 0 | BB32: 0 | BC32: =BA32/BB32 -> #DIV/0! | BD32: =BC32/C32 -> #DIV/0!
A33: VGood | B33: 270790 | C33: =B33/F25 -> 130.06244 | D33: 7050 | E33: 0 | F33: 0 | G33: =E33/F33 -> #DIV/0! | H33: =G33/C33 -> #DIV/0! | I33: 0 | J33: 0 | K33: =I33/J33 -> #DIV/0! | L33: =K33/C33 -> #DIV/0! | M33: 0 | N33: 0 | O33: =M33/N33 -> #DIV/0! | P33: =O33/C33 -> #DIV/0! | Q33: 0 | R33: 0 | S33: =Q33/R33 -> #DIV/0! | T33: =S33/C33 -> #DIV/0! | U33: 0 | V33: 0 | W33: =U33/V33 -> #DIV/0! | X33: =W33/C33 -> #DIV/0! | Y33: 0 | Z33: 0 | AA33: =Y33/Z33 -> #DIV/0! | AB33: =AA33/C33 -> #DIV/0! | AC33: 18880 | AD33: 552 | AE33: =AC33/AD33 -> 34.202899 | AF33: =AE33/C33 -> 0.26297291 | AG33: 0 | AH33: 0 | AI33: =AG33/AH33 -> #DIV/0! | AJ33: =AI33/C33 -> #DIV/0! | AK33: 0 | AL33: 0 | AM33: =AK33/AL33 -> #DIV/0! | AN33: =AM33/C33 -> #DIV/0! | AO33: 0 | AP33: 0 | AQ33: =AO33/AP33 -> #DIV/0! | AR33: =AQ33/C33 -> #DIV/0! | AS33: 0 | AT33: 0 | AU33: =AS33/AT33 -> #DIV/0! | AV33: =AU33/C33 -> #DIV/0! | AW33: 0 | AX33: 0 | AY33: =AW33/AX33 -> #DIV/0! | AZ33: =AY33/C33 -> #DIV/0! | BA33: 0 | BB33: 0 | BC33: =BA33/BB33 -> #DIV/0! | BD33: =BC33/C33 -> #DIV/0!
A34: Excellent | B34: 326750 | C34: =B34/F25 -> 156.94044 | D34: 10950 | E34: 0 | F34: 0 | G34: =E34/F34 -> #DIV/0! | H34: =G34/C34 -> #DIV/0! | I34: 0 | J34: 0 | K34: =I34/J34 -> #DIV/0! | L34: =K34/C34 -> #DIV/0! | M34: 0 | N34: 0 | O34: =M34/N34 -> #DIV/0! | P34: =O34/C34 -> #DIV/0! | Q34: 0 | R34: 0 | S34: =Q34/R34 -> #DIV/0! | T34: =S34/C34 -> #DIV/0! | U34: 0 | V34: 0 | W34: =U34/V34 -> #DIV/0! | X34: =W34/C34 -> #DIV/0! | Y34: 0 | Z34: 0 | AA34: =Y34/Z34 -> #DIV/0! | AB34: =AA34/C34 -> #DIV/0! | AC34: 27050 | AD34: 552 | AE34: =AC34/AD34 -> 49.003623 | AF34: =AE34/C34 -> 0.31224344 | AG34: 0 | AH34: 0 | AI34: =AG34/AH34 -> #DIV/0! | AJ34: =AI34/C34 -> #DIV/0! | AK34: 0 | AL34: 0 | AM34: =AK34/AL34 -> #DIV/0! | AN34: =AM34/C34 -> #DIV/0! | AO34: 0 | AP34: 0 | AQ34: =AO34/AP34 -> #DIV/0! | AR34: =AQ34/C34 -> #DIV/0! | AS34: 0 | AT34: 0 | AU34: =AS34/AT34 -> #DIV/0! | AV34: =AU34/C34 -> #DIV/0! | AW34: 0 | AX34: 0 | AY34: =AW34/AX34 -> #DIV/0! | AZ34: =AY34/C34 -> #DIV/0! | BA34: 0 | BB34: 0 | BC34: =BA34/BB34 -> #DIV/0! | BD34: =BC34/C34 -> #DIV/0!
C35: =AVERAGE(Table1103[MA $/Sq Ft]) -> 89.730342 | D35: =AVERAGE(Table1103[Basic Allowance]) -> 4442.8571 | H35: =AVERAGE(Table1103[Bsmt % Base]) -> #DIV/0! | L35: =AVERAGE(Table1103[[#Headers],[#Data],[UnfBsmt % Base]]) -> #DIV/0! | O35: =AVERAGE(Table1103[LowerVal/SqFt]) -> #DIV/0! | P35: =AVERAGE(Table1103[Lower % Base]) -> #DIV/0! | T35: =AVERAGE(Table1103[Unf Lower % Base]) -> #DIV/0! | X35: =AVERAGE(Table1103[1/2 Story % Base]) -> #DIV/0! | AB35: =AVERAGE(Table1103[2nd Story % Base]) -> #DIV/0! | AE35: =AVERAGE(Table1103[AttGarVal/SqFt]) -> 28.64648 | AF35: =AVERAGE(Table1103[Att Gar % Base]) -> 0.32968404 | AJ35: =AVERAGE(Table1103[Porch % Base]) -> #DIV/0! | AN35: =AVERAGE(Table1103[Cov Porch % Base]) -> #DIV/0! | AR35: =AVERAGE(Table1103[Deck % Base]) -> #DIV/0! | AU35: =AVERAGE(Table1103[CovDeckVal/SqFt]) -> #DIV/0! | AV35: =AVERAGE(Table1103[CovDeck % Base]) -> #DIV/0! | AZ35: =AVERAGE(Table1103[CarP % Base]) -> #DIV/0! | BD35: =AVERAGE(Table1103[EFP % Base]) -> #DIV/0!
B37: Parcel ID: 101893050002010 | E37: Main area sq ft: | F37: 768 | H37: HT: 1 St Masonry | J37: Year Built: | K37: 1948
E38: Basement | I38: Unfinished Basement | M38: Lower | Q38: Unfinished Lower | U38: 1/2 Story | Y38: 2nd Story | AC38: Attached Garage | AG38: Porch | AK38: Covered Porch | AO38: Deck | AS38: Covered Deck | AW38: Carport | BA38: EFP/Sunroom
A39: Grade | B39: Main Area $ | C39: MA $/Sq Ft | D39: Basic Allowance | E39: BsmtVal | F39: Bsmt SqFt | G39: BsmtVal/Sq Ft | H39: Bsmt % Base | I39: UnfBsmtVal | J39: UnfBsmt Sq Ft | K39: UnfBsmtVal/SqFt | L39: UnfBsmt % Base | M39: Lower Value | N39: Lower Sq Ft | O39: LowerVal/SqFt | P39: Lower % Base | Q39: Unf Lower Value | R39: UnfLower Sq Ft | S39: UnfLowVal/SqFt2 | T39: Unf Lower % Base | U39: 1/2 Story Value | V39: 1/2 Story Sq Ft | W39: 1/2 StoryVal/SqFt | X39: 1/2 Story % Base | Y39: 2nd Story Value | Z39: 2nd Sty Sq Ft | AA39: 2ndStyVal/Sqft | AB39: 2nd Story % Base | AC39: Att Gar Value | AD39: Att Gar Sq Ft | AE39: AttGarVal/SqFt | AF39: Att Gar % Base | AG39: Porch Value | AH39: Porch Sq Ft | AI39: PorchVal/SqFt | AJ39: Porch % Base | AK39: Cov Porch Value | AL39: Cov Porch Sq Ft | AM39: CovPrVal/SqFt | AN39: Cov Porch % Base | AO39: Deck Value | AP39: Deck Sq Ft | AQ39: DeckVal/SqFt | AR39: Deck % Base | AS39: Cov Deck Value | AT39: CovDeck Sq Ft | AU39: CovDeckVal/SqFt | AV39: CovDeck % Base | AW39: CarP Value | AX39: CarP Sq Ft | AY39: CarPVal/SqFt | AZ39: CarP % Base | BA39: EFP Value | BB39: EFP Sq Ft | BC39: EFPVal/SqFt | BD39: EFP % Base
A40: Chp | B40: 42240 | C40: =B40/F37 -> 55 | D40: 1525 | E40: 0 | F40: 0 | G40: =E40/F40 -> #DIV/0! | H40: =G40/C40 -> #DIV/0! | I40: 0 | J40: 0 | K40: =I40/J40 -> #DIV/0! | L40: =K40/C40 -> #DIV/0! | M40: 0 | N40: 0 | O40: =M40/N40 -> #DIV/0! | P40: =O40/C40 -> #DIV/0! | Q40: 0 | R40: 0 | S40: =Q40/R40 -> #DIV/0! | T40: =S40/C40 -> #DIV/0! | U40: 0 | V40: 0 | W40: =U40/V40 -> #DIV/0! | X40: =W40/C40 -> #DIV/0! | Y40: 0 | Z40: 0 | AA40: =Y40/Z40 -> #DIV/0! | AB40: =AA40/C40 -> #DIV/0! | AC40: 5570 | AD40: 336 | AE40: =AC40/AD40 -> 16.577381 | AF40: =AE40/C40 -> 0.30140693 | AG40: 0 | AH40: 0 | AI40: =AG40/AH40 -> #DIV/0! | AJ40: =AI40/C40 -> #DIV/0! | AK40: 2190 | AL40: 364 | AM40: =AK40/AL40 -> 6.0164835 | AN40: =AM40/C40 -> 0.10939061 | AO40: 0 | AP40: 0 | AQ40: =AO40/AP40 -> #DIV/0! | AR40: =AQ40/C40 -> #DIV/0! | AS40: 0 | AT40: 0 | AU40: =AS40/AT40 -> #DIV/0! | AV40: =AU40/C40 -> #DIV/0! | AW40: 0 | AX40: 0 | AY40: =AW40/AX40 -> #DIV/0! | AZ40: =AY40/C40 -> #DIV/0! | BA40: 0 | BB40: 0 | BC40: =BA40/BB40 -> #DIV/0! | BD40: =BC40/C40 -> #DIV/0!
A41: Low | B41: 49700 | C41: =B41/F37 -> 64.713542 | D41: 1525 | E41: 0 | F41: 0 | G41: =E41/F41 -> #DIV/0! | H41: =G41/C41 -> #DIV/0! | I41: 0 | J41: 0 | K41: =I41/J41 -> #DIV/0! | L41: =K41/C41 -> #DIV/0! | M41: 0 | N41: 0 | O41: =M41/N41 -> #DIV/0! | P41: =O41/C41 -> #DIV/0! | Q41: 0 | R41: 0 | S41: =Q41/R41 -> #DIV/0! | T41: =S41/C41 -> #DIV/0! | U41: 0 | V41: 0 | W41: =U41/V41 -> #DIV/0! | X41: =W41/C41 -> #DIV/0! | Y41: 0 | Z41: 0 | AA41: =Y41/Z41 -> #DIV/0! | AB41: =AA41/C41 -> #DIV/0! | AC41: 7780 | AD41: 336 | AE41: =AC41/AD41 -> 23.154762 | AF41: =AE41/C41 -> 0.35780397 | AG41: 0 | AH41: 0 | AI41: =AG41/AH41 -> #DIV/0! | AJ41: =AI41/C41 -> #DIV/0! | AK41: 3180 | AL41: 364 | AM41: =AK41/AL41 -> 8.7362637 | AN41: =AM41/C41 -> 0.13499901 | AO41: 0 | AP41: 0 | AQ41: =AO41/AP41 -> #DIV/0! | AR41: =AQ41/C41 -> #DIV/0! | AS41: 0 | AT41: 0 | AU41: =AS41/AT41 -> #DIV/0! | AV41: =AU41/C41 -> #DIV/0! | AW41: 0 | AX41: 0 | AY41: =AW41/AX41 -> #DIV/0! | AZ41: =AY41/C41 -> #DIV/0! | BA41: 0 | BB41: 0 | BC41: =BA41/BB41 -> #DIV/0! | BD41: =BC41/C41 -> #DIV/0!
A42: Fair | B42: 58220 | C42: =B42/F37 -> 75.807292 | D42: 2100 | E42: 0 | F42: 0 | G42: =E42/F42 -> #DIV/0! | H42: =G42/C42 -> #DIV/0! | I42: 0 | J42: 0 | K42: =I42/J42 -> #DIV/0! | L42: =K42/C42 -> #DIV/0! | M42: 0 | N42: 0 | O42: =M42/N42 -> #DIV/0! | P42: =O42/C42 -> #DIV/0! | Q42: 0 | R42: 0 | S42: =Q42/R42 -> #DIV/0! | T42: =S42/C42 -> #DIV/0! | U42: 0 | V42: 0 | W42: =U42/V42 -> #DIV/0! | X42: =W42/C42 -> #DIV/0! | Y42: 0 | Z42: 0 | AA42: =Y42/Z42 -> #DIV/0! | AB42: =AA42/C42 -> #DIV/0! | AC42: 9460 | AD42: 336 | AE42: =AC42/AD42 -> 28.154762 | AF42: =AE42/C42 -> 0.37139913 | AG42: 0 | AH42: 0 | AI42: =AG42/AH42 -> #DIV/0! | AJ42: =AI42/C42 -> #DIV/0! | AK42: 3510 | AL42: 364 | AM42: =AK42/AL42 -> 9.6428571 | AN42: =AM42/C42 -> 0.12720224 | AO42: 0 | AP42: 0 | AQ42: =AO42/AP42 -> #DIV/0! | AR42: =AQ42/C42 -> #DIV/0! | AS42: 0 | AT42: 0 | AU42: =AS42/AT42 -> #DIV/0! | AV42: =AU42/C42 -> #DIV/0! | AW42: 0 | AX42: 0 | AY42: =AW42/AX42 -> #DIV/0! | AZ42: =AY42/C42 -> #DIV/0! | BA42: 0 | BB42: 0 | BC42: =BA42/BB42 -> #DIV/0! | BD42: =BC42/C42 -> #DIV/0!
A43: Avg | B43: 69450 | C43: =B43/F37 -> 90.429688 | D43: 2700 | E43: 0 | F43: 0 | G43: =E43/F43 -> #DIV/0! | H43: =G43/C43 -> #DIV/0! | I43: 0 | J43: 0 | K43: =I43/J43 -> #DIV/0! | L43: =K43/C43 -> #DIV/0! | M43: 0 | N43: 0 | O43: =M43/N43 -> #DIV/0! | P43: =O43/C43 -> #DIV/0! | Q43: 0 | R43: 0 | S43: =Q43/R43 -> #DIV/0! | T43: =S43/C43 -> #DIV/0! | U43: 0 | V43: 0 | W43: =U43/V43 -> #DIV/0! | X43: =W43/C43 -> #DIV/0! | Y43: 0 | Z43: 0 | AA43: =Y43/Z43 -> #DIV/0! | AB43: =AA43/C43 -> #DIV/0! | AC43: 9920 | AD43: 336 | AE43: =AC43/AD43 -> 29.52381 | AF43: =AE43/C43 -> 0.3264836 | AG43: 0 | AH43: 0 | AI43: =AG43/AH43 -> #DIV/0! | AJ43: =AI43/C43 -> #DIV/0! | AK43: 4000 | AL43: 364 | AM43: =AK43/AL43 -> 10.989011 | AN43: =AM43/C43 -> 0.12151995 | AO43: 0 | AP43: 0 | AQ43: =AO43/AP43 -> #DIV/0! | AR43: =AQ43/C43 -> #DIV/0! | AS43: 0 | AT43: 0 | AU43: =AS43/AT43 -> #DIV/0! | AV43: =AU43/C43 -> #DIV/0! | AW43: 0 | AX43: 0 | AY43: =AW43/AX43 -> #DIV/0! | AZ43: =AY43/C43 -> #DIV/0! | BA43: 0 | BB43: 0 | BC43: =BA43/BB43 -> #DIV/0! | BD43: =BC43/C43 -> #DIV/0!
...

Sheet Template
B1: Parcel ID: | E1: Main area sq ft: | F1: 0 | H1: HT: | J1: Year Built:
E2: Basement | I2: Unfinished Basement | M2: Lower | Q2: Unfinished Lower | U2: 1/2 Story | Y2: 2nd Story | AC2: Attached Garage | AG2: Porch | AK2: Covered Porch | AO2: Deck | AS2: Covered Deck | AW2: Carport | BA2: EFP/Sunroom
A3: Grade | B3: Main Area $ | C3: MA $/Sq Ft | D3: Basic Allowance | E3: BsmtVal | F3: Bsmt SqFt | G3: BsmtVal/Sq Ft | H3: Bsmt % Base | I3: UnfBsmtVal | J3: UnfBsmt Sq Ft | K3: UnfBsmtVal/SqFt | L3: UnfBsmt % Base | M3: Lower Value | N3: Lower Sq Ft | O3: LowerVal/SqFt | P3: Lower % Base | Q3: Unf Lower Value | R3: UnfLower Sq Ft | S3: UnfLowVal/SqFt2 | T3: Unf Lower % Base | U3: 1/2 Story Value | V3: 1/2 Story Sq Ft | W3: 1/2 StoryVal/SqFt | X3: 1/2 Story % Base | Y3: 2nd Story Value | Z3: 2nd Sty Sq Ft | AA3: 2ndStyVal/Sqft | AB3: 2nd Story % Base | AC3: Att Gar Value | AD3: Att Gar Sq Ft | AE3: AttGarVal/SqFt | AF3: Att Gar % Base | AG3: Porch Value | AH3: Porch Sq Ft | AI3: PorchVal/SqFt | AJ3: Porch % Base | AK3: Cov Porch Value | AL3: Cov Porch Sq Ft | AM3: CovPrVal/SqFt | AN3: Cov Porch % Base | AO3: Deck Value | AP3: Deck Sq Ft | AQ3: DeckVal/SqFt | AR3: Deck % Base | AS3: Cov Deck Value | AT3: CovDeck Sq Ft | AU3: CovDeckVal/SqFt | AV3: CovDeck % Base | AW3: CarP Value | AX3: CarP Sq Ft | AY3: CarPVal/SqFt | AZ3: CarP % Base | BA3: EFP Value | BB3: EFP Sq Ft | BC3: EFPVal/SqFt | BD3: EFP % Base
A4: Chp | B4: 0 | C4: =B4/F1 -> #DIV/0! | D4: 1525 | E4: 0 | F4: 0 | G4: =E4/F4 -> #DIV/0! | H4: =G4/C4 -> #DIV/0! | I4: 0 | J4: 0 | K4: =I4/J4 -> #DIV/0! | L4: =K4/C4 -> #DIV/0! | M4: 0 | N4: 0 | O4: =M4/N4 -> #DIV/0! | P4: =O4/C4 -> #DIV/0! | Q4: 0 | R4: 0 | S4: =Q4/R4 -> #DIV/0! | T4: =S4/C4 -> #DIV/0! | U4: 0 | V4: 0 | W4: =U4/V4 -> #DIV/0! | X4: =W4/C4 -> #DIV/0! | Y4: 0 | Z4: 0 | AA4: =Y4/Z4 -> #DIV/0! | AB4: =AA4/C4 -> #DIV/0! | AC4: 0 | AD4: 0 | AE4: =AC4/AD4 -> #DIV/0! | AF4: =AE4/C4 -> #DIV/0! | AG4: 0 | AH4: 0 | AI4: =AG4/AH4 -> #DIV/0! | AJ4: =AI4/C4 -> #DIV/0! | AK4: 0 | AL4: 0 | AM4: =AK4/AL4 -> #DIV/0! | AN4: =AM4/C4 -> #DIV/0! | AO4: 0 | AP4: 0 | AQ4: =AO4/AP4 -> #DIV/0! | AR4: =AQ4/C4 -> #DIV/0! | AS4: 0 | AT4: 0 | AU4: =AS4/AT4 -> #DIV/0! | AV4: =AU4/C4 -> #DIV/0! | AW4: 0 | AX4: 0 | AY4: =AW4/AX4 -> #DIV/0! | AZ4: =AY4/C4 -> #DIV/0! | BA4: 0 | BB4: 0 | BC4: =BA4/BB4 -> #DIV/0! | BD4: =BC4/C4 -> #DIV/0!
A5: Low | B5: 0 | C5: =B5/F1 -> #DIV/0! | D5: 1525 | E5: 0 | F5: 0 | G5: =E5/F5 -> #DIV/0! | H5: =G5/C5 -> #DIV/0! | I5: 0 | J5: 0 | K5: =I5/J5 -> #DIV/0! | L5: =K5/C5 -> #DIV/0! | M5: 0 | N5: 0 | O5: =M5/N5 -> #DIV/0! | P5: =O5/C5 -> #DIV/0! | Q5: 0 | R5: 0 | S5: =Q5/R5 -> #DIV/0! | T5: =S5/C5 -> #DIV/0! | U5: 0 | V5: 0 | W5: =U5/V5 -> #DIV/0! | X5: =W5/C5 -> #DIV/0! | Y5: 0 | Z5: 0 | AA5: =Y5/Z5 -> #DIV/0! | AB5: =AA5/C5 -> #DIV/0! | AC5: 0 | AD5: 0 | AE5: =AC5/AD5 -> #DIV/0! | AF5: =AE5/C5 -> #DIV/0! | AG5: 0 | AH5: 0 | AI5: =AG5/AH5 -> #DIV/0! | AJ5: =AI5/C5 -> #DIV/0! | AK5: 0 | AL5: 0 | AM5: =AK5/AL5 -> #DIV/0! | AN5: =AM5/C5 -> #DIV/0! | AO5: 0 | AP5: 0 | AQ5: =AO5/AP5 -> #DIV/0! | AR5: =AQ5/C5 -> #DIV/0! | AS5: 0 | AT5: 0 | AU5: =AS5/AT5 -> #DIV/0! | AV5: =AU5/C5 -> #DIV/0! | AW5: 0 | AX5: 0 | AY5: =AW5/AX5 -> #DIV/0! | AZ5: =AY5/C5 -> #DIV/0! | BA5: 0 | BB5: 0 | BC5: =BA5/BB5 -> #DIV/0! | BD5: =BC5/C5 -> #DIV/0!
A6: Fair | B6: 0 | C6: =B6/F1 -> #DIV/0! | D6: 2100 | E6: 0 | F6: 0 | G6: =E6/F6 -> #DIV/0! | H6: =G6/C6 -> #DIV/0! | I6: 0 | J6: 0 | K6: =I6/J6 -> #DIV/0! | L6: =K6/C6 -> #DIV/0! | M6: 0 | N6: 0 | O6: =M6/N6 -> #DIV/0! | P6: =O6/C6 -> #DIV/0! | Q6: 0 | R6: 0 | S6: =Q6/R6 -> #DIV/0! | T6: =S6/C6 -> #DIV/0! | U6: 0 | V6: 0 | W6: =U6/V6 -> #DIV/0! | X6: =W6/C6 -> #DIV/0! | Y6: 0 | Z6: 0 | AA6: =Y6/Z6 -> #DIV/0! | AB6: =AA6/C6 -> #DIV/0! | AC6: 0 | AD6: 0 | AE6: =AC6/AD6 -> #DIV/0! | AF6: =AE6/C6 -> #DIV/0! | AG6: 0 | AH6: 0 | AI6: =AG6/AH6 -> #DIV/0! | AJ6: =AI6/C6 -> #DIV/0! | AK6: 0 | AL6: 0 | AM6: =AK6/AL6 -> #DIV/0! | AN6: =AM6/C6 -> #DIV/0! | AO6: 0 | AP6: 0 | AQ6: =AO6/AP6 -> #DIV/0! | AR6: =AQ6/C6 -> #DIV/0! | AS6: 0 | AT6: 0 | AU6: =AS6/AT6 -> #DIV/0! | AV6: =AU6/C6 -> #DIV/0! | AW6: 0 | AX6: 0 | AY6: =AW6/AX6 -> #DIV/0! | AZ6: =AY6/C6 -> #DIV/0! | BA6: 0 | BB6: 0 | BC6: =BA6/BB6 -> #DIV/0! | BD6: =BC6/C6 -> #DIV/0!
A7: Avg | B7: 0 | C7: =B7/F1 -> #DIV/0! | D7: 2700 | E7: 0 | F7: 0 | G7: =E7/F7 -> #DIV/0! | H7: =G7/C7 -> #DIV/0! | I7: 0 | J7: 0 | K7: =I7/J7 -> #DIV/0! | L7: =K7/C7 -> #DIV/0! | M7: 0 | N7: 0 | O7: =M7/N7 -> #DIV/0! | P7: =O7/C7 -> #DIV/0! | Q7: 0 | R7: 0 | S7: =Q7/R7 -> #DIV/0! | T7: =S7/C7 -> #DIV/0! | U7: 0 | V7: 0 | W7: =U7/V7 -> #DIV/0! | X7: =W7/C7 -> #DIV/0! | Y7: 0 | Z7: 0 | AA7: =Y7/Z7 -> #DIV/0! | AB7: =AA7/C7 -> #DIV/0! | AC7: 0 | AD7: 0 | AE7: =AC7/AD7 -> #DIV/0! | AF7: =AE7/C7 -> #DIV/0! | AG7: 0 | AH7: 0 | AI7: =AG7/AH7 -> #DIV/0! | AJ7: =AI7/C7 -> #DIV/0! | AK7: 0 | AL7: 0 | AM7: =AK7/AL7 -> #DIV/0! | AN7: =AM7/C7 -> #DIV/0! | AO7: 0 | AP7: 0 | AQ7: =AO7/AP7 -> #DIV/0! | AR7: =AQ7/C7 -> #DIV/0! | AS7: 0 | AT7: 0 | AU7: =AS7/AT7 -> #DIV/0! | AV7: =AU7/C7 -> #DIV/0! | AW7: 0 | AX7: 0 | AY7: =AW7/AX7 -> #DIV/0! | AZ7: =AY7/C7 -> #DIV/0! | BA7: 0 | BB7: 0 | BC7: =BA7/BB7 -> #DIV/0! | BD7: =BC7/C7 -> #DIV/0!
A8: Good | B8: 0 | C8: =B8/F1 -> #DIV/0! | D8: 5250 | E8: 0 | F8: 0 | G8: =E8/F8 -> #DIV/0! | H8: =G8/C8 -> #DIV/0! | I8: 0 | J8: 0 | K8: =I8/J8 -> #DIV/0! | L8: =K8/C8 -> #DIV/0! | M8: 0 | N8: 0 | O8: =M8/N8 -> #DIV/0! | P8: =O8/C8 -> #DIV/0! | Q8: 0 | R8: 0 | S8: =Q8/R8 -> #DIV/0! | T8: =S8/C8 -> #DIV/0! | U8: 0 | V8: 0 | W8: =U8/V8 -> #DIV/0! | X8: =W8/C8 -> #DIV/0! | Y8: 0 | Z8: 0 | AA8: =Y8/Z8 -> #DIV/0! | AB8: =AA8/C8 -> #DIV/0! | AC8: 0 | AD8: 0 | AE8: =AC8/AD8 -> #DIV/0! | AF8: =AE8/C8 -> #DIV/0! | AG8: 0 | AH8: 0 | AI8: =AG8/AH8 -> #DIV/0! | AJ8: =AI8/C8 -> #DIV/0! | AK8: 0 | AL8: 0 | AM8: =AK8/AL8 -> #DIV/0! | AN8: =AM8/C8 -> #DIV/0! | AO8: 0 | AP8: 0 | AQ8: =AO8/AP8 -> #DIV/0! | AR8: =AQ8/C8 -> #DIV/0! | AS8: 0 | AT8: 0 | AU8: =AS8/AT8 -> #DIV/0! | AV8: =AU8/C8 -> #DIV/0! | AW8: 0 | AX8: 0 | AY8: =AW8/AX8 -> #DIV/0! | AZ8: =AY8/C8 -> #DIV/0! | BA8: 0 | BB8: 0 | BC8: =BA8/BB8 -> #DIV/0! | BD8: =BC8/C8 -> #DIV/0!
A9: VGood | B9: 0 | C9: =B9/F1 -> #DIV/0! | D9: 7050 | E9: 0 | F9: 0 | G9: =E9/F9 -> #DIV/0! | H9: =G9/C9 -> #DIV/0! | I9: 0 | J9: 0 | K9: =I9/J9 -> #DIV/0! | L9: =K9/C9 -> #DIV/0! | M9: 0 | N9: 0 | O9: =M9/N9 -> #DIV/0! | P9: =O9/C9 -> #DIV/0! | Q9: 0 | R9: 0 | S9: =Q9/R9 -> #DIV/0! | T9: =S9/C9 -> #DIV/0! | U9: 0 | V9: 0 | W9: =U9/V9 -> #DIV/0! | X9: =W9/C9 -> #DIV/0! | Y9: 0 | Z9: 0 | AA9: =Y9/Z9 -> #DIV/0! | AB9: =AA9/C9 -> #DIV/0! | AC9: 0 | AD9: 0 | AE9: =AC9/AD9 -> #DIV/0! | AF9: =AE9/C9 -> #DIV/0! | AG9: 0 | AH9: 0 | AI9: =AG9/AH9 -> #DIV/0! | AJ9: =AI9/C9 -> #DIV/0! | AK9: 0 | AL9: 0 | AM9: =AK9/AL9 -> #DIV/0! | AN9: =AM9/C9 -> #DIV/0! | AO9: 0 | AP9: 0 | AQ9: =AO9/AP9 -> #DIV/0! | AR9: =AQ9/C9 -> #DIV/0! | AS9: 0 | AT9: 0 | AU9: =AS9/AT9 -> #DIV/0! | AV9: =AU9/C9 -> #DIV/0! | AW9: 0 | AX9: 0 | AY9: =AW9/AX9 -> #DIV/0! | AZ9: =AY9/C9 -> #DIV/0! | BA9: 0 | BB9: 0 | BC9: =BA9/BB9 -> #DIV/0! | BD9: =BC9/C9 -> #DIV/0!
